2017-05-15 10:04:55,414:basehttp "GET / HTTP/1.1" 200 1767
2017-05-15 10:05:08,014:basehttp "GET / HTTP/1.1" 200 1767
2017-05-15 10:20:13,409:basehttp "GET / HTTP/1.1" 200 1767
2017-05-15 10:20:19,339:basehttp "GET /admin/ HTTP/1.1" 302 0
2017-05-15 10:20:19,365:basehttp "GET /admin/login/?next=/admin/ HTTP/1.1" 200 1653
2017-05-15 10:20:19,381:basehttp "GET /static/admin/css/login.css HTTP/1.1" 304 0
2017-05-15 10:20:19,381:basehttp "GET /static/admin/css/base.css HTTP/1.1" 304 0
2017-05-15 10:20:19,386:basehttp "GET /static/admin/css/fonts.css HTTP/1.1" 304 0
2017-05-15 10:20:19,399:basehttp "GET /static/admin/fonts/Roboto-Regular-webfont.woff HTTP/1.1" 304 0
2017-05-15 10:20:19,407:basehttp "GET /static/admin/fonts/Roboto-Light-webfont.woff HTTP/1.1" 304 0
2017-05-15 10:20:33,448:basehttp "GET /admi HTTP/1.1" 404 1914
2017-05-15 10:20:37,011:basehttp "GET /admin/login/?next=/admin/ HTTP/1.1" 200 1653
2017-05-15 10:20:42,635:basehttp "GET /admin/login/?next=/admin/ HTTP/1.1" 200 1653
2017-05-15 10:21:08,463:exception Internal Server Error: /admin/login/
Traceback (most recent call last):
  File "/home/taiga/.virtualenvs/taiga/lib/python3.4/site-packages/django/db/backends/utils.py", line 64, in execute
    return self.cursor.execute(sql, params)
psycopg2.ProgrammingError: relation "auth_user" does not exist
LINE 1: ...user"."is_active", "auth_user"."date_joined" FROM "auth_user...
                                                             ^


The above exception was the direct cause of the following exception:

Traceback (most recent call last):
  File "/home/taiga/.virtualenvs/taiga/lib/python3.4/site-packages/django/core/handlers/exception.py", line 42, in inner
    response = get_response(request)
  File "/home/taiga/.virtualenvs/taiga/lib/python3.4/site-packages/django/core/handlers/base.py", line 187, in _get_response
    response = self.process_exception_by_middleware(e, request)
  File "/home/taiga/.virtualenvs/taiga/lib/python3.4/site-packages/django/core/handlers/base.py", line 185, in _get_response
    response = wrapped_callback(request, *callback_args, **callback_kwargs)
  File "/home/taiga/.virtualenvs/taiga/lib/python3.4/site-packages/django/views/decorators/cache.py", line 57, in _wrapped_view_func
    response = view_func(request, *args, **kwargs)
  File "/home/taiga/.virtualenvs/taiga/lib/python3.4/site-packages/django/contrib/admin/sites.py", line 377, in login
    return login(request, **defaults)
  File "/home/taiga/.virtualenvs/taiga/lib/python3.4/site-packages/django/contrib/auth/views.py", line 47, in inner
    return func(*args, **kwargs)
  File "/home/taiga/.virtualenvs/taiga/lib/python3.4/site-packages/django/views/decorators/debug.py", line 76, in sensitive_post_parameters_wrapper
    return view(request, *args, **kwargs)
  File "/home/taiga/.virtualenvs/taiga/lib/python3.4/site-packages/django/utils/decorators.py", line 149, in _wrapped_view
    response = view_func(request, *args, **kwargs)
  File "/home/taiga/.virtualenvs/taiga/lib/python3.4/site-packages/django/views/decorators/cache.py", line 57, in _wrapped_view_func
    response = view_func(request, *args, **kwargs)
  File "/home/taiga/.virtualenvs/taiga/lib/python3.4/site-packages/django/contrib/auth/views.py", line 81, in login
    if form.is_valid():
  File "/home/taiga/.virtualenvs/taiga/lib/python3.4/site-packages/django/forms/forms.py", line 169, in is_valid
    return self.is_bound and not self.errors
  File "/home/taiga/.virtualenvs/taiga/lib/python3.4/site-packages/django/forms/forms.py", line 161, in errors
    self.full_clean()
  File "/home/taiga/.virtualenvs/taiga/lib/python3.4/site-packages/django/forms/forms.py", line 371, in full_clean
    self._clean_form()
  File "/home/taiga/.virtualenvs/taiga/lib/python3.4/site-packages/django/forms/forms.py", line 398, in _clean_form
    cleaned_data = self.clean()
  File "/home/taiga/.virtualenvs/taiga/lib/python3.4/site-packages/django/contrib/auth/forms.py", line 191, in clean
    self.user_cache = authenticate(username=username, password=password)
  File "/home/taiga/.virtualenvs/taiga/lib/python3.4/site-packages/django/contrib/auth/__init__.py", line 74, in authenticate
    user = backend.authenticate(**credentials)
  File "/home/taiga/.virtualenvs/taiga/lib/python3.4/site-packages/django/contrib/auth/backends.py", line 17, in authenticate
    user = UserModel._default_manager.get_by_natural_key(username)
  File "/home/taiga/.virtualenvs/taiga/lib/python3.4/site-packages/django/contrib/auth/base_user.py", line 48, in get_by_natural_key
    return self.get(**{self.model.USERNAME_FIELD: username})
  File "/home/taiga/.virtualenvs/taiga/lib/python3.4/site-packages/django/db/models/manager.py", line 85, in manager_method
    return getattr(self.get_queryset(), name)(*args, **kwargs)
  File "/home/taiga/.virtualenvs/taiga/lib/python3.4/site-packages/django/db/models/query.py", line 379, in get
    num = len(clone)
  File "/home/taiga/.virtualenvs/taiga/lib/python3.4/site-packages/django/db/models/query.py", line 238, in __len__
    self._fetch_all()
  File "/home/taiga/.virtualenvs/taiga/lib/python3.4/site-packages/django/db/models/query.py", line 1087, in _fetch_all
    self._result_cache = list(self.iterator())
  File "/home/taiga/.virtualenvs/taiga/lib/python3.4/site-packages/django/db/models/query.py", line 54, in __iter__
    results = compiler.execute_sql()
  File "/home/taiga/.virtualenvs/taiga/lib/python3.4/site-packages/django/db/models/sql/compiler.py", line 835, in execute_sql
    cursor.execute(sql, params)
  File "/home/taiga/.virtualenvs/taiga/lib/python3.4/site-packages/django/db/backends/utils.py", line 79, in execute
    return super(CursorDebugWrapper, self).execute(sql, params)
  File "/home/taiga/.virtualenvs/taiga/lib/python3.4/site-packages/django/db/backends/utils.py", line 64, in execute
    return self.cursor.execute(sql, params)
  File "/home/taiga/.virtualenvs/taiga/lib/python3.4/site-packages/django/db/utils.py", line 94, in __exit__
    six.reraise(dj_exc_type, dj_exc_value, traceback)
  File "/home/taiga/.virtualenvs/taiga/lib/python3.4/site-packages/django/utils/six.py", line 685, in reraise
    raise value.with_traceback(tb)
  File "/home/taiga/.virtualenvs/taiga/lib/python3.4/site-packages/django/db/backends/utils.py", line 64, in execute
    return self.cursor.execute(sql, params)
django.db.utils.ProgrammingError: relation "auth_user" does not exist
LINE 1: ...user"."is_active", "auth_user"."date_joined" FROM "auth_user...
                                                             ^

2017-05-15 10:21:08,600:basehttp "POST /admin/login/?next=/admin/ HTTP/1.1" 500 186663
2017-05-15 10:21:27,431:basehttp "GET /admin/login/?next=/admin/ HTTP/1.1" 200 1653
2017-05-15 10:29:43,768:basehttp "POST /admin/login/?next=/admin/ HTTP/1.1" 302 0
2017-05-15 10:29:43,799:basehttp "GET /admin/ HTTP/1.1" 200 2779
2017-05-15 10:29:43,812:basehttp "GET /static/admin/css/base.css HTTP/1.1" 304 0
2017-05-15 10:29:43,813:basehttp "GET /static/admin/css/dashboard.css HTTP/1.1" 200 434
2017-05-15 10:29:43,817:basehttp "GET /static/admin/css/fonts.css HTTP/1.1" 304 0
2017-05-15 10:29:43,839:basehttp "GET /static/admin/fonts/Roboto-Light-webfont.woff HTTP/1.1" 304 0
2017-05-15 10:29:43,843:basehttp "GET /static/admin/fonts/Roboto-Regular-webfont.woff HTTP/1.1" 304 0
2017-05-15 10:29:43,854:basehttp "GET /static/admin/img/icon-addlink.svg HTTP/1.1" 200 331
2017-05-15 10:29:43,863:basehttp "GET /static/admin/img/icon-changelink.svg HTTP/1.1" 200 380
2017-05-15 10:29:43,866:basehttp "GET /static/admin/fonts/Roboto-Bold-webfont.woff HTTP/1.1" 200 82564
2017-05-15 10:29:51,148:basehttp "GET /admin/auth/user/ HTTP/1.1" 200 6358
2017-05-15 10:29:51,180:basehttp "GET /static/admin/js/core.js HTTP/1.1" 200 7976
2017-05-15 10:29:51,180:basehttp "GET /static/admin/css/changelists.css HTTP/1.1" 200 6117
2017-05-15 10:29:51,195:basehttp "GET /static/admin/js/vendor/jquery/jquery.js HTTP/1.1" 200 258648
2017-05-15 10:29:51,197:basehttp "GET /static/admin/js/admin/RelatedObjectLookups.js HTTP/1.1" 200 6577
2017-05-15 10:29:51,198:basehttp "GET /static/admin/js/jquery.init.js HTTP/1.1" 200 363
2017-05-15 10:29:51,217:basehttp "GET /admin/jsi18n/ HTTP/1.1" 200 3189
2017-05-15 10:29:51,221:basehttp "GET /static/admin/js/actions.js HTTP/1.1" 200 6501
2017-05-15 10:29:51,231:basehttp "GET /static/admin/js/prepopulate.js HTTP/1.1" 200 1538
2017-05-15 10:29:51,230:basehttp "GET /static/admin/js/urlify.js HTTP/1.1" 200 8186
2017-05-15 10:29:51,233:basehttp "GET /static/admin/js/vendor/xregexp/xregexp.js HTTP/1.1" 200 128820
2017-05-15 10:29:51,240:basehttp "GET /static/admin/img/search.svg HTTP/1.1" 200 458
2017-05-15 10:29:51,259:basehttp "GET /static/admin/img/icon-yes.svg HTTP/1.1" 200 436
2017-05-15 10:29:51,339:basehttp "GET /static/admin/img/tooltag-add.svg HTTP/1.1" 200 331
2017-05-15 10:29:51,343:basehttp "GET /static/admin/img/sorting-icons.svg HTTP/1.1" 200 1097
2017-05-15 10:29:59,719:basehttp "GET /admin/auth/user/1/change/ HTTP/1.1" 200 13422
2017-05-15 10:29:59,737:basehttp "GET /static/admin/css/forms.css HTTP/1.1" 200 7750
2017-05-15 10:29:59,744:basehttp "GET /static/admin/js/SelectBox.js HTTP/1.1" 200 5755
2017-05-15 10:29:59,749:basehttp "GET /static/admin/js/SelectFilter2.js HTTP/1.1" 200 12389
2017-05-15 10:29:59,752:basehttp "GET /static/admin/js/calendar.js HTTP/1.1" 200 7790
2017-05-15 10:29:59,780:basehttp "GET /admin/jsi18n/ HTTP/1.1" 200 3189
2017-05-15 10:29:59,780:basehttp "GET /static/admin/js/admin/DateTimeShortcuts.js HTTP/1.1" 200 20529
2017-05-15 10:29:59,783:basehttp "GET /static/admin/css/widgets.css HTTP/1.1" 200 10340
2017-05-15 10:29:59,797:basehttp "GET /static/admin/js/change_form.js HTTP/1.1" 200 698
2017-05-15 10:29:59,806:basehttp "GET /static/admin/js/prepopulate_init.js HTTP/1.1" 200 495
2017-05-15 10:29:59,946:basehttp "GET /static/admin/img/icon-unknown.svg HTTP/1.1" 200 655
2017-05-15 10:29:59,947:basehttp "GET /static/admin/img/icon-unknown-alt.svg HTTP/1.1" 200 655
2017-05-15 10:29:59,947:basehttp "GET /static/admin/img/selector-icons.svg HTTP/1.1" 200 3291
2017-05-15 10:29:59,964:basehttp "GET /static/admin/img/icon-clock.svg HTTP/1.1" 200 677
2017-05-15 10:29:59,966:basehttp "GET /static/admin/img/icon-calendar.svg HTTP/1.1" 200 1086
2017-05-15 10:30:02,724:basehttp "GET /admin/auth/user/1/password/ HTTP/1.1" 200 2931
2017-05-15 10:30:02,754:basehttp "GET /admin/jsi18n/ HTTP/1.1" 200 3189
2017-05-15 10:30:09,786:basehttp "POST /admin/auth/user/1/password/ HTTP/1.1" 200 3185
2017-05-15 10:30:09,811:basehttp "GET /admin/jsi18n/ HTTP/1.1" 200 3189
2017-05-15 10:31:27,751:basehttp "GET /admin/auth/user/ HTTP/1.1" 200 6358
2017-05-15 10:31:27,789:basehttp "GET /admin/jsi18n/ HTTP/1.1" 200 3189
2017-05-15 10:31:29,685:basehttp "GET /admin/auth/ HTTP/1.1" 200 2705
2017-05-15 10:31:30,771:basehttp "GET /admin/ HTTP/1.1" 200 2779
2017-05-15 10:33:43,090:basehttp "GET /admin/ HTTP/1.1" 200 2779
2017-05-15 10:33:44,643:basehttp "GET /admin/ HTTP/1.1" 200 2779
2017-05-15 10:33:57,668:utils (0.002) 
            SELECT c.relname, c.relkind
            FROM pg_catalog.pg_class c
            LEFT JOIN pg_catalog.pg_namespace n ON n.oid = c.relnamespace
            WHERE c.relkind IN ('r', 'v')
                AND n.nspname NOT IN ('pg_catalog', 'pg_toast')
                AND pg_catalog.pg_table_is_visible(c.oid); args=None
2017-05-15 10:33:57,671:utils (0.000) SELECT "django_migrations"."app", "django_migrations"."name" FROM "django_migrations"; args=()
2017-05-15 10:34:33,755:utils (0.003) SELECT "django_session"."session_key", "django_session"."session_data", "django_session"."expire_date" FROM "django_session" WHERE ("django_session"."session_key" = 'rsurau6awymdbispk8z934jmobg72z1l' AND "django_session"."expire_date" > '2017-05-15T10:34:33.746733+00:00'::timestamptz); args=('rsurau6awymdbispk8z934jmobg72z1l', datetime.datetime(2017, 5, 15, 10, 34, 33, 746733, tzinfo=<UTC>))
2017-05-15 10:34:33,758:utils (0.001) SELECT "auth_user"."id", "auth_user"."password", "auth_user"."last_login", "auth_user"."is_superuser", "auth_user"."username", "auth_user"."first_name", "auth_user"."last_name", "auth_user"."email", "auth_user"."is_staff", "auth_user"."is_active", "auth_user"."date_joined" FROM "auth_user" WHERE "auth_user"."id" = 1; args=(1,)
2017-05-15 10:34:33,785:base Exception while resolving variable 'is_popup' in template 'admin/index.html'.
Traceback (most recent call last):
  File "/home/taiga/.virtualenvs/taiga/lib/python3.4/site-packages/django/template/base.py", line 885, in _resolve_lookup
    current = current[bit]
  File "/home/taiga/.virtualenvs/taiga/lib/python3.4/site-packages/django/template/context.py", line 75, in __getitem__
    raise KeyError(key)
KeyError: 'is_popup'

During handling of the above exception, another exception occurred:

Traceback (most recent call last):
  File "/home/taiga/.virtualenvs/taiga/lib/python3.4/site-packages/django/template/base.py", line 891, in _resolve_lookup
    if isinstance(current, BaseContext) and getattr(type(current), bit):
AttributeError: type object 'RequestContext' has no attribute 'is_popup'

During handling of the above exception, another exception occurred:

Traceback (most recent call last):
  File "/home/taiga/.virtualenvs/taiga/lib/python3.4/site-packages/django/template/base.py", line 900, in _resolve_lookup
    current = current[int(bit)]
ValueError: invalid literal for int() with base 10: 'is_popup'

During handling of the above exception, another exception occurred:

Traceback (most recent call last):
  File "/home/taiga/.virtualenvs/taiga/lib/python3.4/site-packages/django/template/base.py", line 907, in _resolve_lookup
    (bit, current))  # missing attribute
django.template.base.VariableDoesNotExist: Failed lookup for key [is_popup] in "[{'None': None, 'True': True, 'False': False}, {'DEFAULT_MESSAGE_LEVELS': {'INFO': 20, 'SUCCESS': 25, 'DEBUG': 10, 'ERROR': 40, 'WARNING': 30}, 'messages': <django.contrib.messages.storage.fallback.FallbackStorage object at 0x7f165bddea20>, 'request': <WSGIRequest: GET '/admin/'>, 'perms': <django.contrib.auth.context_processors.PermWrapper object at 0x7f165ac7d080>, 'csrf_token': <SimpleLazyObject: <function csrf.<locals>._get_val at 0x7f165b56cbf8>>, 'user': <SimpleLazyObject: <User: admin>>}, {}, {'site_title': <django.utils.functional.lazy.<locals>.__proxy__ object at 0x7f165f2557f0>, 'site_header': <django.utils.functional.lazy.<locals>.__proxy__ object at 0x7f165f255898>, 'site_url': '/', 'available_apps': [{'name': <django.utils.functional.lazy.<locals>.__proxy__ object at 0x7f165f260b70>, 'has_module_perms': True, 'app_label': 'auth', 'models': [{'name': <django.utils.functional.lazy.<locals>.__proxy__ object at 0x7f165b52fcc0>, 'perms': {'add': True, 'change': True, 'delete': True}, 'admin_url': '/admin/auth/group/', 'object_name': 'Group', 'add_url': '/admin/auth/group/add/'}, {'name': <django.utils.functional.lazy.<locals>.__proxy__ object at 0x7f165b52f320>, 'perms': {'add': True, 'change': True, 'delete': True}, 'admin_url': '/admin/auth/user/', 'object_name': 'User', 'add_url': '/admin/auth/user/add/'}], 'app_url': '/admin/auth/'}], 'app_list': [{'name': <django.utils.functional.lazy.<locals>.__proxy__ object at 0x7f165f260b70>, 'has_module_perms': True, 'app_label': 'auth', 'models': [{'name': <django.utils.functional.lazy.<locals>.__proxy__ object at 0x7f165b52f160>, 'perms': {'add': True, 'change': True, 'delete': True}, 'admin_url': '/admin/auth/group/', 'object_name': 'Group', 'add_url': '/admin/auth/group/add/'}, {'name': <django.utils.functional.lazy.<locals>.__proxy__ object at 0x7f165b52f668>, 'perms': {'add': True, 'change': True, 'delete': True}, 'admin_url': '/admin/auth/user/', 'object_name': 'User', 'add_url': '/admin/auth/user/add/'}], 'app_url': '/admin/auth/'}], 'LANGUAGE_BIDI': False, 'title': <django.utils.functional.lazy.<locals>.__proxy__ object at 0x7f165f255da0>, 'LANGUAGE_CODE': 'en-us', 'has_permission': True}]"
2017-05-15 10:34:33,789:base Exception while resolving variable 'is_popup' in template 'admin/index.html'.
Traceback (most recent call last):
  File "/home/taiga/.virtualenvs/taiga/lib/python3.4/site-packages/django/template/base.py", line 885, in _resolve_lookup
    current = current[bit]
  File "/home/taiga/.virtualenvs/taiga/lib/python3.4/site-packages/django/template/context.py", line 75, in __getitem__
    raise KeyError(key)
KeyError: 'is_popup'

During handling of the above exception, another exception occurred:

Traceback (most recent call last):
  File "/home/taiga/.virtualenvs/taiga/lib/python3.4/site-packages/django/template/base.py", line 891, in _resolve_lookup
    if isinstance(current, BaseContext) and getattr(type(current), bit):
AttributeError: type object 'RequestContext' has no attribute 'is_popup'

During handling of the above exception, another exception occurred:

Traceback (most recent call last):
  File "/home/taiga/.virtualenvs/taiga/lib/python3.4/site-packages/django/template/base.py", line 900, in _resolve_lookup
    current = current[int(bit)]
ValueError: invalid literal for int() with base 10: 'is_popup'

During handling of the above exception, another exception occurred:

Traceback (most recent call last):
  File "/home/taiga/.virtualenvs/taiga/lib/python3.4/site-packages/django/template/base.py", line 907, in _resolve_lookup
    (bit, current))  # missing attribute
django.template.base.VariableDoesNotExist: Failed lookup for key [is_popup] in "[{'None': None, 'True': True, 'False': False}, {'DEFAULT_MESSAGE_LEVELS': {'INFO': 20, 'SUCCESS': 25, 'DEBUG': 10, 'ERROR': 40, 'WARNING': 30}, 'messages': <django.contrib.messages.storage.fallback.FallbackStorage object at 0x7f165bddea20>, 'request': <WSGIRequest: GET '/admin/'>, 'perms': <django.contrib.auth.context_processors.PermWrapper object at 0x7f165ac7d080>, 'csrf_token': <SimpleLazyObject: <function csrf.<locals>._get_val at 0x7f165b56cbf8>>, 'user': <SimpleLazyObject: <User: admin>>}, {}, {'site_title': <django.utils.functional.lazy.<locals>.__proxy__ object at 0x7f165f2557f0>, 'site_header': <django.utils.functional.lazy.<locals>.__proxy__ object at 0x7f165f255898>, 'site_url': '/', 'available_apps': [{'name': <django.utils.functional.lazy.<locals>.__proxy__ object at 0x7f165f260b70>, 'has_module_perms': True, 'app_label': 'auth', 'models': [{'name': <django.utils.functional.lazy.<locals>.__proxy__ object at 0x7f165b52fcc0>, 'perms': {'add': True, 'change': True, 'delete': True}, 'admin_url': '/admin/auth/group/', 'object_name': 'Group', 'add_url': '/admin/auth/group/add/'}, {'name': <django.utils.functional.lazy.<locals>.__proxy__ object at 0x7f165b52f320>, 'perms': {'add': True, 'change': True, 'delete': True}, 'admin_url': '/admin/auth/user/', 'object_name': 'User', 'add_url': '/admin/auth/user/add/'}], 'app_url': '/admin/auth/'}], 'app_list': [{'name': <django.utils.functional.lazy.<locals>.__proxy__ object at 0x7f165f260b70>, 'has_module_perms': True, 'app_label': 'auth', 'models': [{'name': <django.utils.functional.lazy.<locals>.__proxy__ object at 0x7f165b52f160>, 'perms': {'add': True, 'change': True, 'delete': True}, 'admin_url': '/admin/auth/group/', 'object_name': 'Group', 'add_url': '/admin/auth/group/add/'}, {'name': <django.utils.functional.lazy.<locals>.__proxy__ object at 0x7f165b52f668>, 'perms': {'add': True, 'change': True, 'delete': True}, 'admin_url': '/admin/auth/user/', 'object_name': 'User', 'add_url': '/admin/auth/user/add/'}], 'app_url': '/admin/auth/'}], 'LANGUAGE_BIDI': False, 'title': <django.utils.functional.lazy.<locals>.__proxy__ object at 0x7f165f255da0>, 'LANGUAGE_CODE': 'en-us', 'has_permission': True}]"
2017-05-15 10:34:33,795:utils (0.001) SELECT "django_admin_log"."id", "django_admin_log"."action_time", "django_admin_log"."user_id", "django_admin_log"."content_type_id", "django_admin_log"."object_id", "django_admin_log"."object_repr", "django_admin_log"."action_flag", "django_admin_log"."change_message", "auth_user"."id", "auth_user"."password", "auth_user"."last_login", "auth_user"."is_superuser", "auth_user"."username", "auth_user"."first_name", "auth_user"."last_name", "auth_user"."email", "auth_user"."is_staff", "auth_user"."is_active", "auth_user"."date_joined", "django_content_type"."id", "django_content_type"."app_label", "django_content_type"."model" FROM "django_admin_log" INNER JOIN "auth_user" ON ("django_admin_log"."user_id" = "auth_user"."id") LEFT OUTER JOIN "django_content_type" ON ("django_admin_log"."content_type_id" = "django_content_type"."id") WHERE "django_admin_log"."user_id" = 1 ORDER BY "django_admin_log"."action_time" DESC LIMIT 10; args=(1,)
2017-05-15 10:34:33,796:basehttp "GET /admin/ HTTP/1.1" 200 2779
2017-05-15 10:34:50,080:utils (0.005) SELECT "django_session"."session_key", "django_session"."session_data", "django_session"."expire_date" FROM "django_session" WHERE ("django_session"."session_key" = 'rsurau6awymdbispk8z934jmobg72z1l' AND "django_session"."expire_date" > '2017-05-15T10:34:50.062495+00:00'::timestamptz); args=('rsurau6awymdbispk8z934jmobg72z1l', datetime.datetime(2017, 5, 15, 10, 34, 50, 62495, tzinfo=<UTC>))
2017-05-15 10:34:50,090:utils (0.005) SELECT "auth_user"."id", "auth_user"."password", "auth_user"."last_login", "auth_user"."is_superuser", "auth_user"."username", "auth_user"."first_name", "auth_user"."last_name", "auth_user"."email", "auth_user"."is_staff", "auth_user"."is_active", "auth_user"."date_joined" FROM "auth_user" WHERE "auth_user"."id" = 1; args=(1,)
2017-05-15 10:34:50,109:base Exception while resolving variable 'is_popup' in template 'admin/index.html'.
Traceback (most recent call last):
  File "/home/taiga/.virtualenvs/taiga/lib/python3.4/site-packages/django/template/base.py", line 885, in _resolve_lookup
    current = current[bit]
  File "/home/taiga/.virtualenvs/taiga/lib/python3.4/site-packages/django/template/context.py", line 75, in __getitem__
    raise KeyError(key)
KeyError: 'is_popup'

During handling of the above exception, another exception occurred:

Traceback (most recent call last):
  File "/home/taiga/.virtualenvs/taiga/lib/python3.4/site-packages/django/template/base.py", line 891, in _resolve_lookup
    if isinstance(current, BaseContext) and getattr(type(current), bit):
AttributeError: type object 'RequestContext' has no attribute 'is_popup'

During handling of the above exception, another exception occurred:

Traceback (most recent call last):
  File "/home/taiga/.virtualenvs/taiga/lib/python3.4/site-packages/django/template/base.py", line 900, in _resolve_lookup
    current = current[int(bit)]
ValueError: invalid literal for int() with base 10: 'is_popup'

During handling of the above exception, another exception occurred:

Traceback (most recent call last):
  File "/home/taiga/.virtualenvs/taiga/lib/python3.4/site-packages/django/template/base.py", line 907, in _resolve_lookup
    (bit, current))  # missing attribute
django.template.base.VariableDoesNotExist: Failed lookup for key [is_popup] in "[{'None': None, 'True': True, 'False': False}, {'DEFAULT_MESSAGE_LEVELS': {'INFO': 20, 'SUCCESS': 25, 'DEBUG': 10, 'ERROR': 40, 'WARNING': 30}, 'messages': <django.contrib.messages.storage.fallback.FallbackStorage object at 0x7f165acf73c8>, 'request': <WSGIRequest: GET '/admin/'>, 'perms': <django.contrib.auth.context_processors.PermWrapper object at 0x7f165ac9a2b0>, 'csrf_token': <SimpleLazyObject: <function csrf.<locals>._get_val at 0x7f165b533378>>, 'user': <SimpleLazyObject: <User: admin>>}, {}, {'site_title': <django.utils.functional.lazy.<locals>.__proxy__ object at 0x7f165f2557f0>, 'site_header': <django.utils.functional.lazy.<locals>.__proxy__ object at 0x7f165f255898>, 'site_url': '/', 'available_apps': [{'name': <django.utils.functional.lazy.<locals>.__proxy__ object at 0x7f165f260b70>, 'has_module_perms': True, 'app_label': 'auth', 'models': [{'name': <django.utils.functional.lazy.<locals>.__proxy__ object at 0x7f165acf7588>, 'perms': {'add': True, 'change': True, 'delete': True}, 'admin_url': '/admin/auth/group/', 'object_name': 'Group', 'add_url': '/admin/auth/group/add/'}, {'name': <django.utils.functional.lazy.<locals>.__proxy__ object at 0x7f165acf74e0>, 'perms': {'add': True, 'change': True, 'delete': True}, 'admin_url': '/admin/auth/user/', 'object_name': 'User', 'add_url': '/admin/auth/user/add/'}], 'app_url': '/admin/auth/'}], 'app_list': [{'name': <django.utils.functional.lazy.<locals>.__proxy__ object at 0x7f165f260b70>, 'has_module_perms': True, 'app_label': 'auth', 'models': [{'name': <django.utils.functional.lazy.<locals>.__proxy__ object at 0x7f165acf7908>, 'perms': {'add': True, 'change': True, 'delete': True}, 'admin_url': '/admin/auth/group/', 'object_name': 'Group', 'add_url': '/admin/auth/group/add/'}, {'name': <django.utils.functional.lazy.<locals>.__proxy__ object at 0x7f165acf78d0>, 'perms': {'add': True, 'change': True, 'delete': True}, 'admin_url': '/admin/auth/user/', 'object_name': 'User', 'add_url': '/admin/auth/user/add/'}], 'app_url': '/admin/auth/'}], 'LANGUAGE_BIDI': False, 'title': <django.utils.functional.lazy.<locals>.__proxy__ object at 0x7f165f255da0>, 'LANGUAGE_CODE': 'en-us', 'has_permission': True}]"
2017-05-15 10:34:50,111:base Exception while resolving variable 'is_popup' in template 'admin/index.html'.
Traceback (most recent call last):
  File "/home/taiga/.virtualenvs/taiga/lib/python3.4/site-packages/django/template/base.py", line 885, in _resolve_lookup
    current = current[bit]
  File "/home/taiga/.virtualenvs/taiga/lib/python3.4/site-packages/django/template/context.py", line 75, in __getitem__
    raise KeyError(key)
KeyError: 'is_popup'

During handling of the above exception, another exception occurred:

Traceback (most recent call last):
  File "/home/taiga/.virtualenvs/taiga/lib/python3.4/site-packages/django/template/base.py", line 891, in _resolve_lookup
    if isinstance(current, BaseContext) and getattr(type(current), bit):
AttributeError: type object 'RequestContext' has no attribute 'is_popup'

During handling of the above exception, another exception occurred:

Traceback (most recent call last):
  File "/home/taiga/.virtualenvs/taiga/lib/python3.4/site-packages/django/template/base.py", line 900, in _resolve_lookup
    current = current[int(bit)]
ValueError: invalid literal for int() with base 10: 'is_popup'

During handling of the above exception, another exception occurred:

Traceback (most recent call last):
  File "/home/taiga/.virtualenvs/taiga/lib/python3.4/site-packages/django/template/base.py", line 907, in _resolve_lookup
    (bit, current))  # missing attribute
django.template.base.VariableDoesNotExist: Failed lookup for key [is_popup] in "[{'None': None, 'True': True, 'False': False}, {'DEFAULT_MESSAGE_LEVELS': {'INFO': 20, 'SUCCESS': 25, 'DEBUG': 10, 'ERROR': 40, 'WARNING': 30}, 'messages': <django.contrib.messages.storage.fallback.FallbackStorage object at 0x7f165acf73c8>, 'request': <WSGIRequest: GET '/admin/'>, 'perms': <django.contrib.auth.context_processors.PermWrapper object at 0x7f165ac9a2b0>, 'csrf_token': <SimpleLazyObject: <function csrf.<locals>._get_val at 0x7f165b533378>>, 'user': <SimpleLazyObject: <User: admin>>}, {}, {'site_title': <django.utils.functional.lazy.<locals>.__proxy__ object at 0x7f165f2557f0>, 'site_header': <django.utils.functional.lazy.<locals>.__proxy__ object at 0x7f165f255898>, 'site_url': '/', 'available_apps': [{'name': <django.utils.functional.lazy.<locals>.__proxy__ object at 0x7f165f260b70>, 'has_module_perms': True, 'app_label': 'auth', 'models': [{'name': <django.utils.functional.lazy.<locals>.__proxy__ object at 0x7f165acf7588>, 'perms': {'add': True, 'change': True, 'delete': True}, 'admin_url': '/admin/auth/group/', 'object_name': 'Group', 'add_url': '/admin/auth/group/add/'}, {'name': <django.utils.functional.lazy.<locals>.__proxy__ object at 0x7f165acf74e0>, 'perms': {'add': True, 'change': True, 'delete': True}, 'admin_url': '/admin/auth/user/', 'object_name': 'User', 'add_url': '/admin/auth/user/add/'}], 'app_url': '/admin/auth/'}], 'app_list': [{'name': <django.utils.functional.lazy.<locals>.__proxy__ object at 0x7f165f260b70>, 'has_module_perms': True, 'app_label': 'auth', 'models': [{'name': <django.utils.functional.lazy.<locals>.__proxy__ object at 0x7f165acf7908>, 'perms': {'add': True, 'change': True, 'delete': True}, 'admin_url': '/admin/auth/group/', 'object_name': 'Group', 'add_url': '/admin/auth/group/add/'}, {'name': <django.utils.functional.lazy.<locals>.__proxy__ object at 0x7f165acf78d0>, 'perms': {'add': True, 'change': True, 'delete': True}, 'admin_url': '/admin/auth/user/', 'object_name': 'User', 'add_url': '/admin/auth/user/add/'}], 'app_url': '/admin/auth/'}], 'LANGUAGE_BIDI': False, 'title': <django.utils.functional.lazy.<locals>.__proxy__ object at 0x7f165f255da0>, 'LANGUAGE_CODE': 'en-us', 'has_permission': True}]"
2017-05-15 10:34:50,121:utils (0.003) SELECT "django_admin_log"."id", "django_admin_log"."action_time", "django_admin_log"."user_id", "django_admin_log"."content_type_id", "django_admin_log"."object_id", "django_admin_log"."object_repr", "django_admin_log"."action_flag", "django_admin_log"."change_message", "auth_user"."id", "auth_user"."password", "auth_user"."last_login", "auth_user"."is_superuser", "auth_user"."username", "auth_user"."first_name", "auth_user"."last_name", "auth_user"."email", "auth_user"."is_staff", "auth_user"."is_active", "auth_user"."date_joined", "django_content_type"."id", "django_content_type"."app_label", "django_content_type"."model" FROM "django_admin_log" INNER JOIN "auth_user" ON ("django_admin_log"."user_id" = "auth_user"."id") LEFT OUTER JOIN "django_content_type" ON ("django_admin_log"."content_type_id" = "django_content_type"."id") WHERE "django_admin_log"."user_id" = 1 ORDER BY "django_admin_log"."action_time" DESC LIMIT 10; args=(1,)
2017-05-15 10:34:50,127:basehttp "GET /admin/ HTTP/1.1" 200 2779
2017-05-15 10:34:51,872:utils (0.004) SELECT "django_session"."session_key", "django_session"."session_data", "django_session"."expire_date" FROM "django_session" WHERE ("django_session"."session_key" = 'rsurau6awymdbispk8z934jmobg72z1l' AND "django_session"."expire_date" > '2017-05-15T10:34:51.855988+00:00'::timestamptz); args=('rsurau6awymdbispk8z934jmobg72z1l', datetime.datetime(2017, 5, 15, 10, 34, 51, 855988, tzinfo=<UTC>))
2017-05-15 10:34:51,876:utils (0.001) SELECT "auth_user"."id", "auth_user"."password", "auth_user"."last_login", "auth_user"."is_superuser", "auth_user"."username", "auth_user"."first_name", "auth_user"."last_name", "auth_user"."email", "auth_user"."is_staff", "auth_user"."is_active", "auth_user"."date_joined" FROM "auth_user" WHERE "auth_user"."id" = 1; args=(1,)
2017-05-15 10:34:51,896:base Exception while resolving variable 'is_popup' in template 'admin/index.html'.
Traceback (most recent call last):
  File "/home/taiga/.virtualenvs/taiga/lib/python3.4/site-packages/django/template/base.py", line 885, in _resolve_lookup
    current = current[bit]
  File "/home/taiga/.virtualenvs/taiga/lib/python3.4/site-packages/django/template/context.py", line 75, in __getitem__
    raise KeyError(key)
KeyError: 'is_popup'

During handling of the above exception, another exception occurred:

Traceback (most recent call last):
  File "/home/taiga/.virtualenvs/taiga/lib/python3.4/site-packages/django/template/base.py", line 891, in _resolve_lookup
    if isinstance(current, BaseContext) and getattr(type(current), bit):
AttributeError: type object 'RequestContext' has no attribute 'is_popup'

During handling of the above exception, another exception occurred:

Traceback (most recent call last):
  File "/home/taiga/.virtualenvs/taiga/lib/python3.4/site-packages/django/template/base.py", line 900, in _resolve_lookup
    current = current[int(bit)]
ValueError: invalid literal for int() with base 10: 'is_popup'

During handling of the above exception, another exception occurred:

Traceback (most recent call last):
  File "/home/taiga/.virtualenvs/taiga/lib/python3.4/site-packages/django/template/base.py", line 907, in _resolve_lookup
    (bit, current))  # missing attribute
django.template.base.VariableDoesNotExist: Failed lookup for key [is_popup] in "[{'None': None, 'True': True, 'False': False}, {'DEFAULT_MESSAGE_LEVELS': {'INFO': 20, 'SUCCESS': 25, 'DEBUG': 10, 'ERROR': 40, 'WARNING': 30}, 'messages': <django.contrib.messages.storage.fallback.FallbackStorage object at 0x7f165acdeb70>, 'request': <WSGIRequest: GET '/admin/'>, 'perms': <django.contrib.auth.context_processors.PermWrapper object at 0x7f165acf7080>, 'csrf_token': <SimpleLazyObject: <function csrf.<locals>._get_val at 0x7f165b533378>>, 'user': <SimpleLazyObject: <User: admin>>}, {}, {'site_title': <django.utils.functional.lazy.<locals>.__proxy__ object at 0x7f165f2557f0>, 'site_header': <django.utils.functional.lazy.<locals>.__proxy__ object at 0x7f165f255898>, 'site_url': '/', 'available_apps': [{'name': <django.utils.functional.lazy.<locals>.__proxy__ object at 0x7f165f260b70>, 'has_module_perms': True, 'app_label': 'auth', 'models': [{'name': <django.utils.functional.lazy.<locals>.__proxy__ object at 0x7f165acdeba8>, 'perms': {'add': True, 'change': True, 'delete': True}, 'admin_url': '/admin/auth/group/', 'object_name': 'Group', 'add_url': '/admin/auth/group/add/'}, {'name': <django.utils.functional.lazy.<locals>.__proxy__ object at 0x7f165acdeef0>, 'perms': {'add': True, 'change': True, 'delete': True}, 'admin_url': '/admin/auth/user/', 'object_name': 'User', 'add_url': '/admin/auth/user/add/'}], 'app_url': '/admin/auth/'}], 'app_list': [{'name': <django.utils.functional.lazy.<locals>.__proxy__ object at 0x7f165f260b70>, 'has_module_perms': True, 'app_label': 'auth', 'models': [{'name': <django.utils.functional.lazy.<locals>.__proxy__ object at 0x7f165acde668>, 'perms': {'add': True, 'change': True, 'delete': True}, 'admin_url': '/admin/auth/group/', 'object_name': 'Group', 'add_url': '/admin/auth/group/add/'}, {'name': <django.utils.functional.lazy.<locals>.__proxy__ object at 0x7f165acde748>, 'perms': {'add': True, 'change': True, 'delete': True}, 'admin_url': '/admin/auth/user/', 'object_name': 'User', 'add_url': '/admin/auth/user/add/'}], 'app_url': '/admin/auth/'}], 'LANGUAGE_BIDI': False, 'title': <django.utils.functional.lazy.<locals>.__proxy__ object at 0x7f165f255da0>, 'LANGUAGE_CODE': 'en-us', 'has_permission': True}]"
2017-05-15 10:34:51,897:base Exception while resolving variable 'is_popup' in template 'admin/index.html'.
Traceback (most recent call last):
  File "/home/taiga/.virtualenvs/taiga/lib/python3.4/site-packages/django/template/base.py", line 885, in _resolve_lookup
    current = current[bit]
  File "/home/taiga/.virtualenvs/taiga/lib/python3.4/site-packages/django/template/context.py", line 75, in __getitem__
    raise KeyError(key)
KeyError: 'is_popup'

During handling of the above exception, another exception occurred:

Traceback (most recent call last):
  File "/home/taiga/.virtualenvs/taiga/lib/python3.4/site-packages/django/template/base.py", line 891, in _resolve_lookup
    if isinstance(current, BaseContext) and getattr(type(current), bit):
AttributeError: type object 'RequestContext' has no attribute 'is_popup'

During handling of the above exception, another exception occurred:

Traceback (most recent call last):
  File "/home/taiga/.virtualenvs/taiga/lib/python3.4/site-packages/django/template/base.py", line 900, in _resolve_lookup
    current = current[int(bit)]
ValueError: invalid literal for int() with base 10: 'is_popup'

During handling of the above exception, another exception occurred:

Traceback (most recent call last):
  File "/home/taiga/.virtualenvs/taiga/lib/python3.4/site-packages/django/template/base.py", line 907, in _resolve_lookup
    (bit, current))  # missing attribute
django.template.base.VariableDoesNotExist: Failed lookup for key [is_popup] in "[{'None': None, 'True': True, 'False': False}, {'DEFAULT_MESSAGE_LEVELS': {'INFO': 20, 'SUCCESS': 25, 'DEBUG': 10, 'ERROR': 40, 'WARNING': 30}, 'messages': <django.contrib.messages.storage.fallback.FallbackStorage object at 0x7f165acdeb70>, 'request': <WSGIRequest: GET '/admin/'>, 'perms': <django.contrib.auth.context_processors.PermWrapper object at 0x7f165acf7080>, 'csrf_token': <SimpleLazyObject: <function csrf.<locals>._get_val at 0x7f165b533378>>, 'user': <SimpleLazyObject: <User: admin>>}, {}, {'site_title': <django.utils.functional.lazy.<locals>.__proxy__ object at 0x7f165f2557f0>, 'site_header': <django.utils.functional.lazy.<locals>.__proxy__ object at 0x7f165f255898>, 'site_url': '/', 'available_apps': [{'name': <django.utils.functional.lazy.<locals>.__proxy__ object at 0x7f165f260b70>, 'has_module_perms': True, 'app_label': 'auth', 'models': [{'name': <django.utils.functional.lazy.<locals>.__proxy__ object at 0x7f165acdeba8>, 'perms': {'add': True, 'change': True, 'delete': True}, 'admin_url': '/admin/auth/group/', 'object_name': 'Group', 'add_url': '/admin/auth/group/add/'}, {'name': <django.utils.functional.lazy.<locals>.__proxy__ object at 0x7f165acdeef0>, 'perms': {'add': True, 'change': True, 'delete': True}, 'admin_url': '/admin/auth/user/', 'object_name': 'User', 'add_url': '/admin/auth/user/add/'}], 'app_url': '/admin/auth/'}], 'app_list': [{'name': <django.utils.functional.lazy.<locals>.__proxy__ object at 0x7f165f260b70>, 'has_module_perms': True, 'app_label': 'auth', 'models': [{'name': <django.utils.functional.lazy.<locals>.__proxy__ object at 0x7f165acde668>, 'perms': {'add': True, 'change': True, 'delete': True}, 'admin_url': '/admin/auth/group/', 'object_name': 'Group', 'add_url': '/admin/auth/group/add/'}, {'name': <django.utils.functional.lazy.<locals>.__proxy__ object at 0x7f165acde748>, 'perms': {'add': True, 'change': True, 'delete': True}, 'admin_url': '/admin/auth/user/', 'object_name': 'User', 'add_url': '/admin/auth/user/add/'}], 'app_url': '/admin/auth/'}], 'LANGUAGE_BIDI': False, 'title': <django.utils.functional.lazy.<locals>.__proxy__ object at 0x7f165f255da0>, 'LANGUAGE_CODE': 'en-us', 'has_permission': True}]"
2017-05-15 10:34:51,907:utils (0.002) SELECT "django_admin_log"."id", "django_admin_log"."action_time", "django_admin_log"."user_id", "django_admin_log"."content_type_id", "django_admin_log"."object_id", "django_admin_log"."object_repr", "django_admin_log"."action_flag", "django_admin_log"."change_message", "auth_user"."id", "auth_user"."password", "auth_user"."last_login", "auth_user"."is_superuser", "auth_user"."username", "auth_user"."first_name", "auth_user"."last_name", "auth_user"."email", "auth_user"."is_staff", "auth_user"."is_active", "auth_user"."date_joined", "django_content_type"."id", "django_content_type"."app_label", "django_content_type"."model" FROM "django_admin_log" INNER JOIN "auth_user" ON ("django_admin_log"."user_id" = "auth_user"."id") LEFT OUTER JOIN "django_content_type" ON ("django_admin_log"."content_type_id" = "django_content_type"."id") WHERE "django_admin_log"."user_id" = 1 ORDER BY "django_admin_log"."action_time" DESC LIMIT 10; args=(1,)
2017-05-15 10:34:51,911:basehttp "GET /admin/ HTTP/1.1" 200 2779
2017-05-15 10:35:05,077:basehttp "GET / HTTP/1.1" 200 1767
2017-05-15 10:35:30,925:basehttp "GET / HTTP/1.1" 200 1767
2017-05-15 10:35:33,287:basehttp "GET /admin/ HTTP/1.1" 200 2779
2017-05-15 10:35:36,372:basehttp "GET /admin/auth/user/ HTTP/1.1" 200 6358
2017-05-15 10:35:36,397:basehttp "GET /admin/jsi18n/ HTTP/1.1" 200 3189
2017-05-15 10:35:38,185:basehttp "GET /admin/ HTTP/1.1" 200 2779
2017-05-15 10:35:40,105:basehttp "GET /admin/auth/group/ HTTP/1.1" 200 3379
2017-05-15 10:35:40,134:basehttp "GET /admin/jsi18n/ HTTP/1.1" 200 3189
2017-05-15 10:35:44,690:basehttp "GET /admin/ HTTP/1.1" 200 2779
2017-05-15 10:35:46,192:basehttp "GET /admin/auth/user/ HTTP/1.1" 200 6358
2017-05-15 10:35:46,225:basehttp "GET /admin/jsi18n/ HTTP/1.1" 200 3189
2017-05-15 11:49:35,466:basehttp "GET /admin/auth/user/ HTTP/1.1" 200 6358
2017-05-15 11:49:35,493:basehttp "GET /static/admin/css/base.css HTTP/1.1" 304 0
2017-05-15 11:49:35,496:basehttp "GET /static/admin/js/jquery.init.js HTTP/1.1" 304 0
2017-05-15 11:49:35,521:basehttp "GET /static/admin/css/changelists.css HTTP/1.1" 304 0
2017-05-15 11:49:35,522:basehttp "GET /static/admin/js/core.js HTTP/1.1" 304 0
2017-05-15 11:49:35,523:basehttp "GET /static/admin/js/vendor/jquery/jquery.js HTTP/1.1" 304 0
2017-05-15 11:49:35,539:basehttp "GET /static/admin/css/fonts.css HTTP/1.1" 304 0
2017-05-15 11:49:35,540:basehttp "GET /static/admin/js/admin/RelatedObjectLookups.js HTTP/1.1" 304 0
2017-05-15 11:49:35,542:basehttp "GET /admin/jsi18n/ HTTP/1.1" 200 3189
2017-05-15 11:49:35,545:basehttp "GET /static/admin/js/actions.js HTTP/1.1" 304 0
2017-05-15 11:49:35,561:basehttp "GET /static/admin/js/urlify.js HTTP/1.1" 304 0
2017-05-15 11:49:35,562:basehttp "GET /static/admin/js/prepopulate.js HTTP/1.1" 304 0
2017-05-15 11:49:35,563:basehttp "GET /static/admin/js/vendor/xregexp/xregexp.js HTTP/1.1" 304 0
2017-05-15 11:49:35,566:basehttp "GET /static/admin/img/search.svg HTTP/1.1" 304 0
2017-05-15 11:49:35,590:basehttp "GET /static/admin/img/icon-yes.svg HTTP/1.1" 304 0
2017-05-15 11:49:35,651:basehttp "GET /static/admin/fonts/Roboto-Light-webfont.woff HTTP/1.1" 304 0
2017-05-15 11:49:35,655:basehttp "GET /static/admin/fonts/Roboto-Bold-webfont.woff HTTP/1.1" 304 0
2017-05-15 11:49:35,658:basehttp "GET /static/admin/fonts/Roboto-Regular-webfont.woff HTTP/1.1" 304 0
2017-05-15 11:49:35,658:basehttp "GET /static/admin/img/tooltag-add.svg HTTP/1.1" 304 0
2017-05-15 11:49:35,660:basehttp "GET /static/admin/img/sorting-icons.svg HTTP/1.1" 304 0
2017-05-15 11:49:37,839:basehttp "GET /admin/ HTTP/1.1" 200 2779
2017-05-15 11:49:37,850:basehttp "GET /static/admin/css/dashboard.css HTTP/1.1" 304 0
2017-05-15 11:49:37,867:basehttp "GET /static/admin/img/icon-addlink.svg HTTP/1.1" 304 0
2017-05-15 11:49:37,870:basehttp "GET /static/admin/img/icon-changelink.svg HTTP/1.1" 304 0
2017-05-15 11:50:02,790:basehttp "GET /admin/ HTTP/1.1" 200 2779
2017-05-15 12:00:50,785:basehttp "GET /admin/ HTTP/1.1" 200 5363
2017-05-15 12:08:41,503:basehttp "GET /admin/ HTTP/1.1" 200 5363
2017-05-15 12:08:41,529:basehttp "GET /static/admin/css/base.css HTTP/1.1" 304 0
2017-05-15 12:08:41,534:basehttp "GET /static/admin/css/dashboard.css HTTP/1.1" 304 0
2017-05-15 12:08:41,546:basehttp "GET /static/admin/css/fonts.css HTTP/1.1" 304 0
2017-05-15 12:08:41,568:basehttp "GET /static/admin/fonts/Roboto-Light-webfont.woff HTTP/1.1" 304 0
2017-05-15 12:08:41,575:basehttp "GET /static/admin/fonts/Roboto-Bold-webfont.woff HTTP/1.1" 304 0
2017-05-15 12:08:41,577:basehttp "GET /static/admin/fonts/Roboto-Regular-webfont.woff HTTP/1.1" 304 0
2017-05-15 12:08:41,578:basehttp "GET /static/admin/img/icon-addlink.svg HTTP/1.1" 304 0
2017-05-15 12:08:41,580:basehttp "GET /static/admin/img/icon-changelink.svg HTTP/1.1" 304 0
2017-05-15 12:09:12,614:basehttp "GET /admin/users/user/ HTTP/1.1" 200 3022
2017-05-15 12:09:12,631:basehttp "GET /static/admin/css/changelists.css HTTP/1.1" 304 0
2017-05-15 12:09:12,641:basehttp "GET /static/admin/js/core.js HTTP/1.1" 304 0
2017-05-15 12:09:12,643:basehttp "GET /static/admin/js/jquery.init.js HTTP/1.1" 304 0
2017-05-15 12:09:12,648:basehttp "GET /static/admin/js/vendor/jquery/jquery.js HTTP/1.1" 304 0
2017-05-15 12:09:12,654:basehttp "GET /static/admin/js/urlify.js HTTP/1.1" 304 0
2017-05-15 12:09:12,683:basehttp "GET /static/admin/js/admin/RelatedObjectLookups.js HTTP/1.1" 304 0
2017-05-15 12:09:12,684:basehttp "GET /admin/jsi18n/ HTTP/1.1" 200 3189
2017-05-15 12:09:12,686:basehttp "GET /static/admin/js/actions.js HTTP/1.1" 304 0
2017-05-15 12:09:12,687:basehttp "GET /static/admin/js/vendor/xregexp/xregexp.js HTTP/1.1" 304 0
2017-05-15 12:09:12,688:basehttp "GET /static/admin/js/prepopulate.js HTTP/1.1" 304 0
2017-05-15 12:09:12,770:basehttp "GET /static/admin/img/tooltag-add.svg HTTP/1.1" 304 0
2017-05-15 12:09:14,564:basehttp "GET /admin/users/user/add/ HTTP/1.1" 200 5567
2017-05-15 12:09:14,601:basehttp "GET /static/admin/css/forms.css HTTP/1.1" 304 0
2017-05-15 12:09:14,603:basehttp "GET /static/admin/js/calendar.js HTTP/1.1" 304 0
2017-05-15 12:09:14,613:basehttp "GET /static/admin/js/change_form.js HTTP/1.1" 304 0
2017-05-15 12:09:14,614:basehttp "GET /static/admin/js/admin/DateTimeShortcuts.js HTTP/1.1" 304 0
2017-05-15 12:09:14,615:basehttp "GET /admin/jsi18n/ HTTP/1.1" 200 3189
2017-05-15 12:09:14,618:basehttp "GET /static/admin/js/prepopulate_init.js HTTP/1.1" 304 0
2017-05-15 12:09:14,626:basehttp "GET /static/admin/css/widgets.css HTTP/1.1" 304 0
2017-05-15 12:09:14,710:basehttp "GET /static/admin/img/icon-clock.svg HTTP/1.1" 304 0
2017-05-15 12:09:14,716:basehttp "GET /static/admin/img/icon-calendar.svg HTTP/1.1" 304 0
2017-05-15 12:11:17,527:basehttp "GET / HTTP/1.1" 200 1767
2017-05-15 12:11:48,836:basehttp "GET /admin/ HTTP/1.1" 200 5363
2017-05-15 12:11:50,432:basehttp "GET /admin/projects/project/ HTTP/1.1" 200 3055
2017-05-15 12:11:50,474:basehttp "GET /admin/jsi18n/ HTTP/1.1" 200 3189
2017-05-15 12:11:51,932:basehttp "GET /admin/projects/project/add/ HTTP/1.1" 200 4367
2017-05-15 12:11:51,976:basehttp "GET /admin/jsi18n/ HTTP/1.1" 200 3189
2017-05-15 12:11:59,867:basehttp "GET /admin/projects/project/ HTTP/1.1" 200 3055
2017-05-15 12:11:59,896:basehttp "GET /admin/jsi18n/ HTTP/1.1" 200 3189
2017-05-15 12:12:24,677:basehttp "GET /admin/ HTTP/1.1" 200 5363
2017-05-15 12:48:10,249:basehttp "GET /admin/ HTTP/1.1" 200 5363
2017-05-15 12:48:10,264:basehttp "GET /static/admin/css/base.css HTTP/1.1" 304 0
2017-05-15 12:48:10,282:basehttp "GET /static/admin/css/dashboard.css HTTP/1.1" 304 0
2017-05-15 12:48:10,291:basehttp "GET /static/admin/css/fonts.css HTTP/1.1" 304 0
2017-05-15 12:48:10,308:basehttp "GET /static/admin/fonts/Roboto-Light-webfont.woff HTTP/1.1" 304 0
2017-05-15 12:48:10,318:basehttp "GET /static/admin/fonts/Roboto-Bold-webfont.woff HTTP/1.1" 304 0
2017-05-15 12:48:10,341:basehttp "GET /static/admin/img/icon-addlink.svg HTTP/1.1" 304 0
2017-05-15 12:48:10,343:basehttp "GET /static/admin/fonts/Roboto-Regular-webfont.woff HTTP/1.1" 304 0
2017-05-15 12:48:10,345:basehttp "GET /static/admin/img/icon-changelink.svg HTTP/1.1" 304 0
2017-05-15 12:48:13,000:basehttp "GET /admin/users/user/ HTTP/1.1" 200 3022
2017-05-15 12:48:13,036:basehttp "GET /static/admin/js/core.js HTTP/1.1" 304 0
2017-05-15 12:48:13,045:basehttp "GET /static/admin/js/vendor/jquery/jquery.js HTTP/1.1" 304 0
2017-05-15 12:48:13,046:basehttp "GET /static/admin/js/jquery.init.js HTTP/1.1" 304 0
2017-05-15 12:48:13,051:basehttp "GET /static/admin/css/changelists.css HTTP/1.1" 304 0
2017-05-15 12:48:13,065:basehttp "GET /static/admin/js/actions.js HTTP/1.1" 304 0
2017-05-15 12:48:13,067:basehttp "GET /static/admin/js/admin/RelatedObjectLookups.js HTTP/1.1" 304 0
2017-05-15 12:48:13,071:basehttp "GET /admin/jsi18n/ HTTP/1.1" 200 3189
2017-05-15 12:48:13,084:basehttp "GET /static/admin/js/urlify.js HTTP/1.1" 304 0
2017-05-15 12:48:13,084:basehttp "GET /static/admin/js/vendor/xregexp/xregexp.js HTTP/1.1" 304 0
2017-05-15 12:48:13,086:basehttp "GET /static/admin/js/prepopulate.js HTTP/1.1" 304 0
2017-05-15 12:48:13,154:basehttp "GET /static/admin/img/tooltag-add.svg HTTP/1.1" 304 0
2017-05-15 12:48:14,987:basehttp "GET /admin/users/user/add/ HTTP/1.1" 200 5567
2017-05-15 12:48:15,023:basehttp "GET /static/admin/js/calendar.js HTTP/1.1" 304 0
2017-05-15 12:48:15,025:basehttp "GET /static/admin/js/change_form.js HTTP/1.1" 304 0
2017-05-15 12:48:15,025:basehttp "GET /static/admin/js/admin/DateTimeShortcuts.js HTTP/1.1" 304 0
2017-05-15 12:48:15,027:basehttp "GET /static/admin/css/forms.css HTTP/1.1" 304 0
2017-05-15 12:48:15,026:basehttp "GET /static/admin/js/prepopulate_init.js HTTP/1.1" 304 0
2017-05-15 12:48:15,044:basehttp "GET /admin/jsi18n/ HTTP/1.1" 200 3189
2017-05-15 12:48:15,046:basehttp "GET /static/admin/css/widgets.css HTTP/1.1" 304 0
2017-05-15 12:48:15,138:basehttp "GET /static/admin/img/icon-calendar.svg HTTP/1.1" 304 0
2017-05-15 12:48:15,140:basehttp "GET /static/admin/img/icon-clock.svg HTTP/1.1" 304 0
2017-05-15 12:50:01,889:exception Internal Server Error: /admin/users/user/add/
Traceback (most recent call last):
  File "/home/taiga/.virtualenvs/taiga/lib/python3.4/site-packages/django/core/handlers/exception.py", line 42, in inner
    response = get_response(request)
  File "/home/taiga/.virtualenvs/taiga/lib/python3.4/site-packages/django/core/handlers/base.py", line 187, in _get_response
    response = self.process_exception_by_middleware(e, request)
  File "/home/taiga/.virtualenvs/taiga/lib/python3.4/site-packages/django/core/handlers/base.py", line 185, in _get_response
    response = wrapped_callback(request, *callback_args, **callback_kwargs)
  File "/home/taiga/.virtualenvs/taiga/lib/python3.4/site-packages/django/contrib/admin/options.py", line 544, in wrapper
    return self.admin_site.admin_view(view)(*args, **kwargs)
  File "/home/taiga/.virtualenvs/taiga/lib/python3.4/site-packages/django/utils/decorators.py", line 149, in _wrapped_view
    response = view_func(request, *args, **kwargs)
  File "/home/taiga/.virtualenvs/taiga/lib/python3.4/site-packages/django/views/decorators/cache.py", line 57, in _wrapped_view_func
    response = view_func(request, *args, **kwargs)
  File "/home/taiga/.virtualenvs/taiga/lib/python3.4/site-packages/django/contrib/admin/sites.py", line 211, in inner
    return view(request, *args, **kwargs)
  File "/home/taiga/.virtualenvs/taiga/lib/python3.4/site-packages/django/contrib/admin/options.py", line 1509, in add_view
    return self.changeform_view(request, None, form_url, extra_context)
  File "/home/taiga/.virtualenvs/taiga/lib/python3.4/site-packages/django/utils/decorators.py", line 67, in _wrapper
    return bound_func(*args, **kwargs)
  File "/home/taiga/.virtualenvs/taiga/lib/python3.4/site-packages/django/utils/decorators.py", line 149, in _wrapped_view
    response = view_func(request, *args, **kwargs)
  File "/home/taiga/.virtualenvs/taiga/lib/python3.4/site-packages/django/utils/decorators.py", line 63, in bound_func
    return func.__get__(self, type(self))(*args2, **kwargs2)
  File "/usr/lib/python3.4/contextlib.py", line 30, in inner
    return func(*args, **kwds)
  File "/home/taiga/.virtualenvs/taiga/lib/python3.4/site-packages/django/contrib/admin/options.py", line 1441, in changeform_view
    if form.is_valid():
  File "/home/taiga/.virtualenvs/taiga/lib/python3.4/site-packages/django/forms/forms.py", line 169, in is_valid
    return self.is_bound and not self.errors
  File "/home/taiga/.virtualenvs/taiga/lib/python3.4/site-packages/django/forms/forms.py", line 161, in errors
    self.full_clean()
  File "/home/taiga/.virtualenvs/taiga/lib/python3.4/site-packages/django/forms/forms.py", line 372, in full_clean
    self._post_clean()
  File "/home/taiga/.virtualenvs/taiga/lib/python3.4/site-packages/django/forms/models.py", line 398, in _post_clean
    self.instance.full_clean(exclude=exclude, validate_unique=False)
  File "/home/taiga/.virtualenvs/taiga/lib/python3.4/site-packages/django/db/models/base.py", line 1217, in full_clean
    self.clean()
  File "/home/taiga/.virtualenvs/taiga/lib/python3.4/site-packages/django/contrib/auth/base_user.py", line 77, in clean
    setattr(self, self.USERNAME_FIELD, self.normalize_username(self.get_username()))
AttributeError: 'User' object has no attribute 'USERNAME_FIELD'
2017-05-15 12:50:01,990:basehttp "POST /admin/users/user/add/ HTTP/1.1" 500 133464
2017-05-15 12:50:15,463:basehttp "GET /admin/users/user/add/ HTTP/1.1" 200 5567
2017-05-15 12:50:49,591:exception Internal Server Error: /admin/users/user/add/
Traceback (most recent call last):
  File "/home/taiga/.virtualenvs/taiga/lib/python3.4/site-packages/django/core/handlers/exception.py", line 42, in inner
    response = get_response(request)
  File "/home/taiga/.virtualenvs/taiga/lib/python3.4/site-packages/django/core/handlers/base.py", line 187, in _get_response
    response = self.process_exception_by_middleware(e, request)
  File "/home/taiga/.virtualenvs/taiga/lib/python3.4/site-packages/django/core/handlers/base.py", line 185, in _get_response
    response = wrapped_callback(request, *callback_args, **callback_kwargs)
  File "/home/taiga/.virtualenvs/taiga/lib/python3.4/site-packages/django/contrib/admin/options.py", line 544, in wrapper
    return self.admin_site.admin_view(view)(*args, **kwargs)
  File "/home/taiga/.virtualenvs/taiga/lib/python3.4/site-packages/django/utils/decorators.py", line 149, in _wrapped_view
    response = view_func(request, *args, **kwargs)
  File "/home/taiga/.virtualenvs/taiga/lib/python3.4/site-packages/django/views/decorators/cache.py", line 57, in _wrapped_view_func
    response = view_func(request, *args, **kwargs)
  File "/home/taiga/.virtualenvs/taiga/lib/python3.4/site-packages/django/contrib/admin/sites.py", line 211, in inner
    return view(request, *args, **kwargs)
  File "/home/taiga/.virtualenvs/taiga/lib/python3.4/site-packages/django/contrib/admin/options.py", line 1509, in add_view
    return self.changeform_view(request, None, form_url, extra_context)
  File "/home/taiga/.virtualenvs/taiga/lib/python3.4/site-packages/django/utils/decorators.py", line 67, in _wrapper
    return bound_func(*args, **kwargs)
  File "/home/taiga/.virtualenvs/taiga/lib/python3.4/site-packages/django/utils/decorators.py", line 149, in _wrapped_view
    response = view_func(request, *args, **kwargs)
  File "/home/taiga/.virtualenvs/taiga/lib/python3.4/site-packages/django/utils/decorators.py", line 63, in bound_func
    return func.__get__(self, type(self))(*args2, **kwargs2)
  File "/usr/lib/python3.4/contextlib.py", line 30, in inner
    return func(*args, **kwds)
  File "/home/taiga/.virtualenvs/taiga/lib/python3.4/site-packages/django/contrib/admin/options.py", line 1441, in changeform_view
    if form.is_valid():
  File "/home/taiga/.virtualenvs/taiga/lib/python3.4/site-packages/django/forms/forms.py", line 169, in is_valid
    return self.is_bound and not self.errors
  File "/home/taiga/.virtualenvs/taiga/lib/python3.4/site-packages/django/forms/forms.py", line 161, in errors
    self.full_clean()
  File "/home/taiga/.virtualenvs/taiga/lib/python3.4/site-packages/django/forms/forms.py", line 372, in full_clean
    self._post_clean()
  File "/home/taiga/.virtualenvs/taiga/lib/python3.4/site-packages/django/forms/models.py", line 398, in _post_clean
    self.instance.full_clean(exclude=exclude, validate_unique=False)
  File "/home/taiga/.virtualenvs/taiga/lib/python3.4/site-packages/django/db/models/base.py", line 1217, in full_clean
    self.clean()
  File "/home/taiga/.virtualenvs/taiga/lib/python3.4/site-packages/django/contrib/auth/base_user.py", line 77, in clean
    setattr(self, self.USERNAME_FIELD, self.normalize_username(self.get_username()))
AttributeError: 'User' object has no attribute 'USERNAME_FIELD'
2017-05-15 12:50:49,689:basehttp "POST /admin/users/user/add/ HTTP/1.1" 500 133442
2017-05-15 12:53:30,333:basehttp "GET /admin/users/user/add/ HTTP/1.1" 200 5567
2017-05-15 12:53:32,669:basehttp "POST /admin/users/user/add/ HTTP/1.1" 302 0
2017-05-15 12:53:32,744:basehttp "GET /admin/users/user/ HTTP/1.1" 200 4336
2017-05-15 12:53:32,777:basehttp "GET /admin/jsi18n/ HTTP/1.1" 200 3189
2017-05-15 12:53:32,850:basehttp "GET /static/admin/img/icon-yes.svg HTTP/1.1" 304 0
2017-05-15 12:53:35,467:basehttp "GET /admin/users/user/add/ HTTP/1.1" 200 5567
2017-05-15 12:53:35,496:basehttp "GET /admin/jsi18n/ HTTP/1.1" 200 3189
2017-05-15 12:53:55,937:basehttp "POST /admin/users/user/add/ HTTP/1.1" 302 0
2017-05-15 12:53:55,988:basehttp "GET /admin/users/user/ HTTP/1.1" 200 4560
2017-05-15 12:53:56,022:basehttp "GET /admin/jsi18n/ HTTP/1.1" 200 3189
2017-05-15 12:53:57,729:basehttp "GET /admin/users/user/add/ HTTP/1.1" 200 5567
2017-05-15 12:53:57,755:basehttp "GET /admin/jsi18n/ HTTP/1.1" 200 3189
2017-05-15 12:54:26,693:basehttp "POST /admin/users/user/add/ HTTP/1.1" 302 0
2017-05-15 12:54:26,760:basehttp "GET /admin/users/user/ HTTP/1.1" 200 4783
2017-05-15 12:54:26,788:basehttp "GET /admin/jsi18n/ HTTP/1.1" 200 3189
2017-05-15 12:54:29,224:basehttp "GET /admin/ HTTP/1.1" 200 6251
2017-05-15 12:54:31,891:basehttp "GET /admin/issues/issue/ HTTP/1.1" 200 3033
2017-05-15 12:54:31,917:basehttp "GET /admin/jsi18n/ HTTP/1.1" 200 3189
2017-05-15 12:54:33,712:basehttp "GET /admin/issues/issue/add/ HTTP/1.1" 200 7547
2017-05-15 12:54:33,732:basehttp "GET /static/admin/img/icon-deletelink.svg HTTP/1.1" 200 392
2017-05-15 12:54:33,744:basehttp "GET /admin/jsi18n/ HTTP/1.1" 200 3189
2017-05-15 12:57:25,711:basehttp "GET /admin/ HTTP/1.1" 200 6251
2017-05-15 12:57:27,087:basehttp "GET /admin/projects/project/ HTTP/1.1" 200 3055
2017-05-15 12:57:27,119:basehttp "GET /admin/jsi18n/ HTTP/1.1" 200 3189
2017-05-15 12:57:28,630:basehttp "GET /admin/projects/project/add/ HTTP/1.1" 200 4367
2017-05-15 12:57:28,654:basehttp "GET /admin/jsi18n/ HTTP/1.1" 200 3189
2017-05-15 12:57:54,560:basehttp "POST /admin/projects/project/add/ HTTP/1.1" 302 0
2017-05-15 12:57:54,612:basehttp "GET /admin/projects/project/add/ HTTP/1.1" 200 4619
2017-05-15 12:57:54,648:basehttp "GET /admin/jsi18n/ HTTP/1.1" 200 3189
2017-05-15 12:58:20,975:basehttp "POST /admin/projects/project/add/ HTTP/1.1" 302 0
2017-05-15 12:58:21,026:basehttp "GET /admin/projects/project/ HTTP/1.1" 200 4690
2017-05-15 12:58:21,060:basehttp "GET /admin/jsi18n/ HTTP/1.1" 200 3189
2017-05-15 12:58:23,173:basehttp "GET /admin/projects/project/add/ HTTP/1.1" 200 4367
2017-05-15 12:58:23,205:basehttp "GET /admin/jsi18n/ HTTP/1.1" 200 3189
2017-05-15 12:58:56,840:basehttp "POST /admin/projects/project/add/ HTTP/1.1" 302 0
2017-05-15 12:58:56,895:basehttp "GET /admin/projects/project/ HTTP/1.1" 200 4962
2017-05-15 12:58:56,930:basehttp "GET /admin/jsi18n/ HTTP/1.1" 200 3189
2017-05-15 12:59:33,411:basehttp "GET /admin/ HTTP/1.1" 200 7214
2017-05-15 12:59:35,872:basehttp "GET /admin/issues/issue/ HTTP/1.1" 200 3033
2017-05-15 12:59:35,906:basehttp "GET /admin/jsi18n/ HTTP/1.1" 200 3189
2017-05-15 12:59:37,559:basehttp "GET /admin/issues/issue/add/ HTTP/1.1" 200 7745
2017-05-15 12:59:37,589:basehttp "GET /admin/jsi18n/ HTTP/1.1" 200 3189
2017-05-15 13:00:16,611:basehttp "POST /admin/issues/issue/add/ HTTP/1.1" 302 0
2017-05-15 13:00:16,663:basehttp "GET /admin/issues/issue/ HTTP/1.1" 200 4376
2017-05-15 13:00:16,699:basehttp "GET /admin/jsi18n/ HTTP/1.1" 200 3189
2017-05-15 13:00:18,998:basehttp "GET /admin/issues/issue/add/ HTTP/1.1" 200 7745
2017-05-15 13:00:19,030:basehttp "GET /admin/jsi18n/ HTTP/1.1" 200 3189
2017-05-15 13:00:47,340:basehttp "POST /admin/issues/issue/add/ HTTP/1.1" 302 0
2017-05-15 13:00:47,403:basehttp "GET /admin/issues/issue/add/ HTTP/1.1" 200 7975
2017-05-15 13:00:47,432:basehttp "GET /admin/jsi18n/ HTTP/1.1" 200 3189
2017-05-15 13:01:24,645:basehttp "POST /admin/issues/issue/add/ HTTP/1.1" 302 0
2017-05-15 13:01:24,699:basehttp "GET /admin/issues/issue/ HTTP/1.1" 200 4886
2017-05-15 13:01:24,741:basehttp "GET /admin/jsi18n/ HTTP/1.1" 200 3189
2017-05-15 13:01:51,499:basehttp "GET /admin/ HTTP/1.1" 200 8131
2017-05-15 13:01:58,325:basehttp "GET /admin/projects/project/ HTTP/1.1" 200 4741
2017-05-15 13:01:58,349:basehttp "GET /admin/jsi18n/ HTTP/1.1" 200 3189
2017-05-15 13:02:02,829:basehttp "GET /admin/ HTTP/1.1" 200 8131
2017-05-15 13:02:04,091:basehttp "GET /admin/issues/issue/ HTTP/1.1" 200 4675
2017-05-15 13:02:04,123:basehttp "GET /admin/jsi18n/ HTTP/1.1" 200 3189
2017-05-15 13:02:07,384:basehttp "GET /admin/issues/issue/add/ HTTP/1.1" 200 7745
2017-05-15 13:02:07,414:basehttp "GET /admin/jsi18n/ HTTP/1.1" 200 3189
2017-05-15 13:02:36,522:basehttp "POST /admin/issues/issue/add/ HTTP/1.1" 302 0
2017-05-15 13:02:36,586:basehttp "GET /admin/issues/issue/add/ HTTP/1.1" 200 7975
2017-05-15 13:02:36,613:basehttp "GET /admin/jsi18n/ HTTP/1.1" 200 3189
2017-05-15 13:02:58,409:basehttp "POST /admin/issues/issue/add/ HTTP/1.1" 302 0
2017-05-15 13:02:58,497:basehttp "GET /admin/issues/issue/add/ HTTP/1.1" 200 8005
2017-05-15 13:02:58,529:basehttp "GET /admin/jsi18n/ HTTP/1.1" 200 3189
2017-05-15 13:03:24,278:basehttp "POST /admin/issues/issue/add/ HTTP/1.1" 302 0
2017-05-15 13:03:24,373:basehttp "GET /admin/issues/issue/add/ HTTP/1.1" 200 7976
2017-05-15 13:03:24,400:basehttp "GET /admin/jsi18n/ HTTP/1.1" 200 3189
2017-05-15 13:03:47,281:basehttp "POST /admin/issues/issue/add/ HTTP/1.1" 302 0
2017-05-15 13:03:47,354:basehttp "GET /admin/issues/issue/add/ HTTP/1.1" 200 7985
2017-05-15 13:03:47,386:basehttp "GET /admin/jsi18n/ HTTP/1.1" 200 3189
2017-05-15 13:04:17,204:basehttp "POST /admin/issues/issue/add/ HTTP/1.1" 302 0
2017-05-15 13:04:17,276:basehttp "GET /admin/issues/issue/add/ HTTP/1.1" 200 7977
2017-05-15 13:04:17,308:basehttp "GET /admin/jsi18n/ HTTP/1.1" 200 3189
2017-05-15 13:04:33,620:basehttp "POST /admin/issues/issue/add/ HTTP/1.1" 302 0
2017-05-15 13:04:33,677:basehttp "GET /admin/issues/issue/ HTTP/1.1" 200 6371
2017-05-15 13:04:33,713:basehttp "GET /admin/jsi18n/ HTTP/1.1" 200 3189
2017-05-15 13:04:44,940:basehttp "GET /admin/ HTTP/1.1" 200 8505
2017-05-15 13:04:46,956:basehttp "GET /admin/users/user/ HTTP/1.1" 200 4603
2017-05-15 13:04:46,987:basehttp "GET /admin/jsi18n/ HTTP/1.1" 200 3189
2017-05-15 13:04:48,631:basehttp "GET /admin/users/user/1/change/ HTTP/1.1" 200 5851
2017-05-15 13:04:48,660:basehttp "GET /admin/jsi18n/ HTTP/1.1" 200 3189
2017-05-15 13:04:52,409:basehttp "GET /admin/ HTTP/1.1" 200 8505
2017-05-15 13:04:53,755:basehttp "GET /admin/timelogs/timelog/ HTTP/1.1" 200 3055
2017-05-15 13:04:53,783:basehttp "GET /admin/jsi18n/ HTTP/1.1" 200 3189
2017-05-15 13:04:55,020:basehttp "GET /admin/timelogs/timelog/add/ HTTP/1.1" 200 8105
2017-05-15 13:04:55,075:basehttp "GET /admin/jsi18n/ HTTP/1.1" 200 3189
2017-05-15 13:05:39,289:basehttp "POST /admin/timelogs/timelog/add/ HTTP/1.1" 302 0
2017-05-15 13:05:39,349:basehttp "GET /admin/timelogs/timelog/add/ HTTP/1.1" 200 8373
2017-05-15 13:05:39,391:basehttp "GET /admin/jsi18n/ HTTP/1.1" 200 3189
2017-05-15 13:05:53,302:basehttp "POST /admin/timelogs/timelog/add/ HTTP/1.1" 302 0
2017-05-15 13:05:53,371:basehttp "GET /admin/timelogs/timelog/add/ HTTP/1.1" 200 8373
2017-05-15 13:05:53,406:basehttp "GET /admin/jsi18n/ HTTP/1.1" 200 3189
2017-05-15 13:06:06,143:basehttp "POST /admin/timelogs/timelog/add/ HTTP/1.1" 302 0
2017-05-15 13:06:06,203:basehttp "GET /admin/timelogs/timelog/add/ HTTP/1.1" 200 8371
2017-05-15 13:06:06,227:basehttp "GET /admin/jsi18n/ HTTP/1.1" 200 3189
2017-05-15 13:06:25,969:basehttp "POST /admin/timelogs/timelog/add/ HTTP/1.1" 302 0
2017-05-15 13:06:26,035:basehttp "GET /admin/timelogs/timelog/add/ HTTP/1.1" 200 8377
2017-05-15 13:06:26,068:basehttp "GET /admin/jsi18n/ HTTP/1.1" 200 3189
2017-05-15 13:06:46,969:basehttp "POST /admin/timelogs/timelog/add/ HTTP/1.1" 302 0
2017-05-15 13:06:47,041:basehttp "GET /admin/timelogs/timelog/ HTTP/1.1" 200 5579
2017-05-15 13:06:47,077:basehttp "GET /admin/jsi18n/ HTTP/1.1" 200 3189
2017-05-15 13:06:49,431:basehttp "GET /admin/timelogs/timelog/add/ HTTP/1.1" 200 8105
2017-05-15 13:06:49,462:basehttp "GET /admin/jsi18n/ HTTP/1.1" 200 3189
2017-05-15 13:07:02,634:basehttp "POST /admin/timelogs/timelog/add/ HTTP/1.1" 302 0
2017-05-15 13:07:02,690:basehttp "GET /admin/timelogs/timelog/add/ HTTP/1.1" 200 8376
2017-05-15 13:07:02,723:basehttp "GET /admin/jsi18n/ HTTP/1.1" 200 3189
2017-05-15 13:07:14,046:basehttp "POST /admin/timelogs/timelog/add/ HTTP/1.1" 302 0
2017-05-15 13:07:14,118:basehttp "GET /admin/timelogs/timelog/add/ HTTP/1.1" 200 8388
2017-05-15 13:07:14,147:basehttp "GET /admin/jsi18n/ HTTP/1.1" 200 3189
2017-05-15 13:07:23,489:basehttp "POST /admin/timelogs/timelog/add/ HTTP/1.1" 302 0
2017-05-15 13:07:23,561:basehttp "GET /admin/timelogs/timelog/add/ HTTP/1.1" 200 8388
2017-05-15 13:07:23,601:basehttp "GET /admin/jsi18n/ HTTP/1.1" 200 3189
2017-05-15 13:07:30,276:basehttp "GET /admin/timelogs/timelog/ HTTP/1.1" 200 6195
2017-05-15 13:07:30,310:basehttp "GET /admin/jsi18n/ HTTP/1.1" 200 3189
2017-05-15 13:07:35,108:basehttp "GET /admin/timelogs/timelog/add/ HTTP/1.1" 200 8105
2017-05-15 13:07:35,138:basehttp "GET /admin/jsi18n/ HTTP/1.1" 200 3189
2017-05-15 13:07:38,296:basehttp "GET /admin/timelogs/timelog/ HTTP/1.1" 200 6195
2017-05-15 13:07:38,331:basehttp "GET /admin/jsi18n/ HTTP/1.1" 200 3189
2017-05-15 13:07:41,572:basehttp "GET /admin/timelogs/timelog/add/ HTTP/1.1" 200 8105
2017-05-15 13:07:41,594:basehttp "GET /admin/jsi18n/ HTTP/1.1" 200 3189
2017-05-15 13:07:52,846:basehttp "POST /admin/timelogs/timelog/add/ HTTP/1.1" 302 0
2017-05-15 13:07:52,911:basehttp "GET /admin/timelogs/timelog/add/ HTTP/1.1" 200 8391
2017-05-15 13:07:52,950:basehttp "GET /admin/jsi18n/ HTTP/1.1" 200 3189
2017-05-15 13:08:24,284:basehttp "POST /admin/timelogs/timelog/add/ HTTP/1.1" 302 0
2017-05-15 13:08:24,377:basehttp "GET /admin/timelogs/timelog/add/ HTTP/1.1" 200 8372
2017-05-15 13:08:24,400:basehttp "GET /admin/jsi18n/ HTTP/1.1" 200 3189
2017-05-15 13:08:36,107:basehttp "POST /admin/timelogs/timelog/add/ HTTP/1.1" 302 0
2017-05-15 13:08:36,171:basehttp "GET /admin/timelogs/timelog/add/ HTTP/1.1" 200 8374
2017-05-15 13:08:36,209:basehttp "GET /admin/jsi18n/ HTTP/1.1" 200 3189
2017-05-15 13:08:49,083:basehttp "POST /admin/timelogs/timelog/add/ HTTP/1.1" 302 0
2017-05-15 13:08:49,151:basehttp "GET /admin/timelogs/timelog/add/ HTTP/1.1" 200 8372
2017-05-15 13:08:49,193:basehttp "GET /admin/jsi18n/ HTTP/1.1" 200 3189
2017-05-15 13:09:02,600:basehttp "POST /admin/timelogs/timelog/add/ HTTP/1.1" 302 0
2017-05-15 13:09:02,667:basehttp "GET /admin/timelogs/timelog/add/ HTTP/1.1" 200 8375
2017-05-15 13:09:02,695:basehttp "GET /admin/jsi18n/ HTTP/1.1" 200 3189
2017-05-15 13:09:20,209:basehttp "POST /admin/timelogs/timelog/add/ HTTP/1.1" 302 0
2017-05-15 13:09:20,272:basehttp "GET /admin/timelogs/timelog/add/ HTTP/1.1" 200 8377
2017-05-15 13:09:20,304:basehttp "GET /admin/jsi18n/ HTTP/1.1" 200 3189
2017-05-15 13:09:33,695:basehttp "POST /admin/timelogs/timelog/add/ HTTP/1.1" 302 0
2017-05-15 13:09:33,763:basehttp "GET /admin/timelogs/timelog/add/ HTTP/1.1" 200 8378
2017-05-15 13:09:33,784:basehttp "GET /admin/jsi18n/ HTTP/1.1" 200 3189
2017-05-15 13:09:44,420:basehttp "POST /admin/timelogs/timelog/add/ HTTP/1.1" 302 0
2017-05-15 13:09:44,499:basehttp "GET /admin/timelogs/timelog/add/ HTTP/1.1" 200 8375
2017-05-15 13:09:44,529:basehttp "GET /admin/jsi18n/ HTTP/1.1" 200 3189
2017-05-15 13:10:00,869:basehttp "POST /admin/timelogs/timelog/add/ HTTP/1.1" 302 0
2017-05-15 13:10:00,939:basehttp "GET /admin/timelogs/timelog/add/ HTTP/1.1" 200 8375
2017-05-15 13:10:00,959:basehttp "GET /static/admin/css/base.css HTTP/1.1" 304 0
2017-05-15 13:10:00,982:basehttp "GET /static/admin/css/forms.css HTTP/1.1" 304 0
2017-05-15 13:10:01,005:basehttp "GET /admin/jsi18n/ HTTP/1.1" 200 3189
2017-05-15 13:10:01,005:basehttp "GET /static/admin/js/core.js HTTP/1.1" 304 0
2017-05-15 13:10:01,007:basehttp "GET /static/admin/js/jquery.init.js HTTP/1.1" 304 0
2017-05-15 13:10:01,014:basehttp "GET /static/admin/js/admin/RelatedObjectLookups.js HTTP/1.1" 304 0
2017-05-15 13:10:01,016:basehttp "GET /static/admin/js/vendor/jquery/jquery.js HTTP/1.1" 304 0
2017-05-15 13:10:01,022:basehttp "GET /static/admin/css/fonts.css HTTP/1.1" 304 0
2017-05-15 13:10:01,033:basehttp "GET /static/admin/css/widgets.css HTTP/1.1" 304 0
2017-05-15 13:10:01,039:basehttp "GET /static/admin/js/urlify.js HTTP/1.1" 304 0
2017-05-15 13:10:01,042:basehttp "GET /static/admin/js/actions.js HTTP/1.1" 304 0
2017-05-15 13:10:01,044:basehttp "GET /static/admin/js/prepopulate.js HTTP/1.1" 304 0
2017-05-15 13:10:01,060:basehttp "GET /static/admin/js/vendor/xregexp/xregexp.js HTTP/1.1" 304 0
2017-05-15 13:10:01,063:basehttp "GET /static/admin/js/calendar.js HTTP/1.1" 304 0
2017-05-15 13:10:01,065:basehttp "GET /static/admin/js/admin/DateTimeShortcuts.js HTTP/1.1" 304 0
2017-05-15 13:10:01,068:basehttp "GET /static/admin/js/change_form.js HTTP/1.1" 304 0
2017-05-15 13:10:01,071:basehttp "GET /static/admin/js/prepopulate_init.js HTTP/1.1" 304 0
2017-05-15 13:10:01,078:basehttp "GET /static/admin/img/icon-changelink.svg HTTP/1.1" 304 0
2017-05-15 13:10:01,084:basehttp "GET /static/admin/img/icon-addlink.svg HTTP/1.1" 304 0
2017-05-15 13:10:01,136:basehttp "GET /static/admin/fonts/Roboto-Light-webfont.woff HTTP/1.1" 304 0
2017-05-15 13:10:01,137:basehttp "GET /static/admin/fonts/Roboto-Regular-webfont.woff HTTP/1.1" 304 0
2017-05-15 13:10:01,138:basehttp "GET /static/admin/fonts/Roboto-Bold-webfont.woff HTTP/1.1" 304 0
2017-05-15 13:10:01,203:basehttp "GET /static/admin/img/icon-calendar.svg HTTP/1.1" 304 0
2017-05-15 13:10:12,625:basehttp "POST /admin/timelogs/timelog/add/ HTTP/1.1" 302 0
2017-05-15 13:10:12,687:basehttp "GET /admin/timelogs/timelog/add/ HTTP/1.1" 200 8378
2017-05-15 13:10:12,713:basehttp "GET /admin/jsi18n/ HTTP/1.1" 200 3189
2017-05-15 13:10:23,850:basehttp "POST /admin/timelogs/timelog/add/ HTTP/1.1" 302 0
2017-05-15 13:10:23,920:basehttp "GET /admin/timelogs/timelog/add/ HTTP/1.1" 200 8378
2017-05-15 13:10:23,955:basehttp "GET /admin/jsi18n/ HTTP/1.1" 200 3189
2017-05-15 13:10:43,016:basehttp "POST /admin/timelogs/timelog/add/ HTTP/1.1" 302 0
2017-05-15 13:10:43,144:basehttp "GET /admin/timelogs/timelog/add/ HTTP/1.1" 200 8375
2017-05-15 13:10:43,176:basehttp "GET /admin/jsi18n/ HTTP/1.1" 200 3189
2017-05-15 13:10:54,110:basehttp "POST /admin/timelogs/timelog/add/ HTTP/1.1" 302 0
2017-05-15 13:10:54,174:basehttp "GET /admin/timelogs/timelog/add/ HTTP/1.1" 200 8377
2017-05-15 13:10:54,193:basehttp "GET /admin/jsi18n/ HTTP/1.1" 200 3189
2017-05-15 13:11:07,876:basehttp "POST /admin/timelogs/timelog/add/ HTTP/1.1" 302 0
2017-05-15 13:11:07,941:basehttp "GET /admin/timelogs/timelog/add/ HTTP/1.1" 200 8377
2017-05-15 13:11:07,970:basehttp "GET /admin/jsi18n/ HTTP/1.1" 200 3189
2017-05-15 13:11:18,248:basehttp "POST /admin/timelogs/timelog/add/ HTTP/1.1" 302 0
2017-05-15 13:11:18,315:basehttp "GET /admin/timelogs/timelog/add/ HTTP/1.1" 200 8389
2017-05-15 13:11:18,345:basehttp "GET /admin/jsi18n/ HTTP/1.1" 200 3189
2017-05-15 13:11:28,266:basehttp "POST /admin/timelogs/timelog/add/ HTTP/1.1" 302 0
2017-05-15 13:11:28,334:basehttp "GET /admin/timelogs/timelog/add/ HTTP/1.1" 200 8389
2017-05-15 13:11:28,365:basehttp "GET /admin/jsi18n/ HTTP/1.1" 200 3189
2017-05-15 13:11:37,686:basehttp "POST /admin/timelogs/timelog/add/ HTTP/1.1" 302 0
2017-05-15 13:11:37,749:basehttp "GET /admin/timelogs/timelog/add/ HTTP/1.1" 200 8389
2017-05-15 13:11:37,780:basehttp "GET /admin/jsi18n/ HTTP/1.1" 200 3189
2017-05-15 13:11:57,026:basehttp "POST /admin/timelogs/timelog/add/ HTTP/1.1" 302 0
2017-05-15 13:11:57,166:basehttp "GET /admin/timelogs/timelog/ HTTP/1.1" 200 11494
2017-05-15 13:11:57,182:basehttp "GET /static/admin/css/changelists.css HTTP/1.1" 304 0
2017-05-15 13:11:57,200:basehttp "GET /admin/jsi18n/ HTTP/1.1" 200 3189
2017-05-15 13:11:57,290:basehttp "GET /static/admin/img/tooltag-add.svg HTTP/1.1" 304 0
2017-05-15 13:54:12,485:basehttp "GET / HTTP/1.1" 404 2008
2017-05-15 13:54:24,175:basehttp "GET /admin/timelogs/timelog/ HTTP/1.1" 200 11245
2017-05-15 13:54:24,198:basehttp "GET /static/admin/css/base.css HTTP/1.1" 304 0
2017-05-15 13:54:24,219:basehttp "GET /static/admin/js/core.js HTTP/1.1" 304 0
2017-05-15 13:54:24,231:basehttp "GET /static/admin/js/vendor/jquery/jquery.js HTTP/1.1" 304 0
2017-05-15 13:54:24,237:basehttp "GET /admin/jsi18n/ HTTP/1.1" 200 3189
2017-05-15 13:54:24,238:basehttp "GET /static/admin/css/changelists.css HTTP/1.1" 304 0
2017-05-15 13:54:24,242:basehttp "GET /static/admin/js/admin/RelatedObjectLookups.js HTTP/1.1" 304 0
2017-05-15 13:54:24,251:basehttp "GET /static/admin/js/jquery.init.js HTTP/1.1" 304 0
2017-05-15 13:54:24,254:basehttp "GET /static/admin/css/fonts.css HTTP/1.1" 304 0
2017-05-15 13:54:24,271:basehttp "GET /static/admin/js/actions.js HTTP/1.1" 304 0
2017-05-15 13:54:24,274:basehttp "GET /static/admin/js/prepopulate.js HTTP/1.1" 304 0
2017-05-15 13:54:24,275:basehttp "GET /static/admin/js/vendor/xregexp/xregexp.js HTTP/1.1" 304 0
2017-05-15 13:54:24,276:basehttp "GET /static/admin/js/urlify.js HTTP/1.1" 304 0
2017-05-15 13:54:24,353:basehttp "GET /static/admin/fonts/Roboto-Bold-webfont.woff HTTP/1.1" 304 0
2017-05-15 13:54:24,354:basehttp "GET /static/admin/fonts/Roboto-Regular-webfont.woff HTTP/1.1" 304 0
2017-05-15 13:54:24,356:basehttp "GET /static/admin/fonts/Roboto-Light-webfont.woff HTTP/1.1" 304 0
2017-05-15 13:54:24,359:basehttp "GET /static/admin/img/tooltag-add.svg HTTP/1.1" 304 0
2017-05-15 13:54:30,327:basehttp "GET /user/ HTTP/1.1" 200 11
2017-05-15 13:58:27,148:basehttp "GET /user/ HTTP/1.1" 200 11
2017-05-15 14:02:42,404:basehttp "GET /user/ HTTP/1.1" 200 11
2017-05-15 14:02:49,528:basehttp "GET /user/ HTTP/1.1" 200 11
2017-05-15 14:13:56,261:basehttp "GET /user/ HTTP/1.1" 200 11
2017-05-15 14:13:58,486:basehttp "GET /admin/timelogs/timelog/ HTTP/1.1" 200 11245
2017-05-15 14:13:58,545:basehttp "GET /admin/jsi18n/ HTTP/1.1" 200 3189
2017-05-15 14:14:01,984:exception Internal Server Error: /user/1
Traceback (most recent call last):
  File "/home/taiga/.virtualenvs/taiga/lib/python3.4/site-packages/django/core/handlers/exception.py", line 42, in inner
    response = get_response(request)
  File "/home/taiga/.virtualenvs/taiga/lib/python3.4/site-packages/django/core/handlers/base.py", line 187, in _get_response
    response = self.process_exception_by_middleware(e, request)
  File "/home/taiga/.virtualenvs/taiga/lib/python3.4/site-packages/django/core/handlers/base.py", line 185, in _get_response
    response = wrapped_callback(request, *callback_args, **callback_kwargs)
  File "/taiga-back/taiga/users/views.py", line 16, in userinfo
    return render(request, user.tmpl, args)
AttributeError: 'User' object has no attribute 'tmpl'
2017-05-15 14:14:02,081:basehttp "GET /user/1 HTTP/1.1" 500 64356
2017-05-15 14:14:06,845:basehttp "GET /user/1/ HTTP/1.1" 404 2285
2017-05-15 14:14:32,567:exception Internal Server Error: /user/1/
Traceback (most recent call last):
  File "/home/taiga/.virtualenvs/taiga/lib/python3.4/site-packages/django/core/handlers/exception.py", line 42, in inner
    response = get_response(request)
  File "/home/taiga/.virtualenvs/taiga/lib/python3.4/site-packages/django/core/handlers/base.py", line 187, in _get_response
    response = self.process_exception_by_middleware(e, request)
  File "/home/taiga/.virtualenvs/taiga/lib/python3.4/site-packages/django/core/handlers/base.py", line 185, in _get_response
    response = wrapped_callback(request, *callback_args, **callback_kwargs)
  File "/taiga-back/taiga/users/views.py", line 16, in userinfo
    return render(request, user.tmpl, args)
AttributeError: 'User' object has no attribute 'tmpl'
2017-05-15 14:14:32,640:basehttp "GET /user/1/ HTTP/1.1" 500 64502
2017-05-15 14:14:50,957:exception Internal Server Error: /user/1/
Traceback (most recent call last):
  File "/home/taiga/.virtualenvs/taiga/lib/python3.4/site-packages/django/core/handlers/exception.py", line 42, in inner
    response = get_response(request)
  File "/home/taiga/.virtualenvs/taiga/lib/python3.4/site-packages/django/core/handlers/base.py", line 187, in _get_response
    response = self.process_exception_by_middleware(e, request)
  File "/home/taiga/.virtualenvs/taiga/lib/python3.4/site-packages/django/core/handlers/base.py", line 185, in _get_response
    response = wrapped_callback(request, *callback_args, **callback_kwargs)
  File "/taiga-back/taiga/users/views.py", line 16, in userinfo
    return render(request, 'user.tmpl', args)
  File "/home/taiga/.virtualenvs/taiga/lib/python3.4/site-packages/django/shortcuts.py", line 30, in render
    content = loader.render_to_string(template_name, context, request, using=using)
  File "/home/taiga/.virtualenvs/taiga/lib/python3.4/site-packages/django/template/loader.py", line 67, in render_to_string
    template = get_template(template_name, using=using)
  File "/home/taiga/.virtualenvs/taiga/lib/python3.4/site-packages/django/template/loader.py", line 25, in get_template
    raise TemplateDoesNotExist(template_name, chain=chain)
django.template.exceptions.TemplateDoesNotExist: user.tmpl
2017-05-15 14:14:51,032:basehttp "GET /user/1/ HTTP/1.1" 500 79263
2017-05-15 14:17:52,788:basehttp "GET /user/1 HTTP/1.1" 301 0
2017-05-15 14:17:52,811:exception Internal Server Error: /user/1/
Traceback (most recent call last):
  File "/home/taiga/.virtualenvs/taiga/lib/python3.4/site-packages/django/core/handlers/exception.py", line 42, in inner
    response = get_response(request)
  File "/home/taiga/.virtualenvs/taiga/lib/python3.4/site-packages/django/core/handlers/base.py", line 187, in _get_response
    response = self.process_exception_by_middleware(e, request)
  File "/home/taiga/.virtualenvs/taiga/lib/python3.4/site-packages/django/core/handlers/base.py", line 185, in _get_response
    response = wrapped_callback(request, *callback_args, **callback_kwargs)
  File "/taiga-back/taiga/users/views.py", line 16, in userinfo
    return render(request, 'user.tmpl', args)
  File "/home/taiga/.virtualenvs/taiga/lib/python3.4/site-packages/django/shortcuts.py", line 30, in render
    content = loader.render_to_string(template_name, context, request, using=using)
  File "/home/taiga/.virtualenvs/taiga/lib/python3.4/site-packages/django/template/loader.py", line 67, in render_to_string
    template = get_template(template_name, using=using)
  File "/home/taiga/.virtualenvs/taiga/lib/python3.4/site-packages/django/template/loader.py", line 25, in get_template
    raise TemplateDoesNotExist(template_name, chain=chain)
django.template.exceptions.TemplateDoesNotExist: user.tmpl
2017-05-15 14:17:52,893:basehttp "GET /user/1/ HTTP/1.1" 500 79559
2017-05-15 14:19:00,994:exception Internal Server Error: /user/1/
Traceback (most recent call last):
  File "/home/taiga/.virtualenvs/taiga/lib/python3.4/site-packages/django/core/handlers/exception.py", line 42, in inner
    response = get_response(request)
  File "/home/taiga/.virtualenvs/taiga/lib/python3.4/site-packages/django/core/handlers/base.py", line 187, in _get_response
    response = self.process_exception_by_middleware(e, request)
  File "/home/taiga/.virtualenvs/taiga/lib/python3.4/site-packages/django/core/handlers/base.py", line 185, in _get_response
    response = wrapped_callback(request, *callback_args, **callback_kwargs)
  File "/taiga-back/taiga/users/views.py", line 16, in userinfo
    return render(request, 'user.tmpl', args)
  File "/home/taiga/.virtualenvs/taiga/lib/python3.4/site-packages/django/shortcuts.py", line 30, in render
    content = loader.render_to_string(template_name, context, request, using=using)
  File "/home/taiga/.virtualenvs/taiga/lib/python3.4/site-packages/django/template/loader.py", line 67, in render_to_string
    template = get_template(template_name, using=using)
  File "/home/taiga/.virtualenvs/taiga/lib/python3.4/site-packages/django/template/loader.py", line 25, in get_template
    raise TemplateDoesNotExist(template_name, chain=chain)
django.template.exceptions.TemplateDoesNotExist: user.tmpl
2017-05-15 14:19:01,080:basehttp "GET /user/1/ HTTP/1.1" 500 79553
2017-05-15 14:19:01,803:exception Internal Server Error: /user/1/
Traceback (most recent call last):
  File "/home/taiga/.virtualenvs/taiga/lib/python3.4/site-packages/django/core/handlers/exception.py", line 42, in inner
    response = get_response(request)
  File "/home/taiga/.virtualenvs/taiga/lib/python3.4/site-packages/django/core/handlers/base.py", line 187, in _get_response
    response = self.process_exception_by_middleware(e, request)
  File "/home/taiga/.virtualenvs/taiga/lib/python3.4/site-packages/django/core/handlers/base.py", line 185, in _get_response
    response = wrapped_callback(request, *callback_args, **callback_kwargs)
  File "/taiga-back/taiga/users/views.py", line 16, in userinfo
    return render(request, 'user.tmpl', args)
  File "/home/taiga/.virtualenvs/taiga/lib/python3.4/site-packages/django/shortcuts.py", line 30, in render
    content = loader.render_to_string(template_name, context, request, using=using)
  File "/home/taiga/.virtualenvs/taiga/lib/python3.4/site-packages/django/template/loader.py", line 67, in render_to_string
    template = get_template(template_name, using=using)
  File "/home/taiga/.virtualenvs/taiga/lib/python3.4/site-packages/django/template/loader.py", line 25, in get_template
    raise TemplateDoesNotExist(template_name, chain=chain)
django.template.exceptions.TemplateDoesNotExist: user.tmpl
2017-05-15 14:19:01,926:basehttp "GET /user/1/ HTTP/1.1" 500 79553
2017-05-15 14:22:34,304:exception Internal Server Error: /user/1/
Traceback (most recent call last):
  File "/home/taiga/.virtualenvs/taiga/lib/python3.4/site-packages/django/core/handlers/exception.py", line 42, in inner
    response = get_response(request)
  File "/home/taiga/.virtualenvs/taiga/lib/python3.4/site-packages/django/core/handlers/base.py", line 187, in _get_response
    response = self.process_exception_by_middleware(e, request)
  File "/home/taiga/.virtualenvs/taiga/lib/python3.4/site-packages/django/core/handlers/base.py", line 185, in _get_response
    response = wrapped_callback(request, *callback_args, **callback_kwargs)
  File "/taiga-back/taiga/users/views.py", line 16, in userinfo
    return render(request, 'user.tmpl', args)
  File "/home/taiga/.virtualenvs/taiga/lib/python3.4/site-packages/django/shortcuts.py", line 30, in render
    content = loader.render_to_string(template_name, context, request, using=using)
  File "/home/taiga/.virtualenvs/taiga/lib/python3.4/site-packages/django/template/loader.py", line 67, in render_to_string
    template = get_template(template_name, using=using)
  File "/home/taiga/.virtualenvs/taiga/lib/python3.4/site-packages/django/template/loader.py", line 25, in get_template
    raise TemplateDoesNotExist(template_name, chain=chain)
django.template.exceptions.TemplateDoesNotExist: user.tmpl
2017-05-15 14:22:34,383:basehttp "GET /user/1/ HTTP/1.1" 500 79601
2017-05-15 14:23:08,079:basehttp "GET /user/1/ HTTP/1.1" 200 8
2017-05-15 14:25:54,938:exception Internal Server Error: /user/1/
Traceback (most recent call last):
  File "/home/taiga/.virtualenvs/taiga/lib/python3.4/site-packages/django/core/handlers/exception.py", line 42, in inner
    response = get_response(request)
  File "/home/taiga/.virtualenvs/taiga/lib/python3.4/site-packages/django/core/handlers/base.py", line 187, in _get_response
    response = self.process_exception_by_middleware(e, request)
  File "/home/taiga/.virtualenvs/taiga/lib/python3.4/site-packages/django/core/handlers/base.py", line 185, in _get_response
    response = wrapped_callback(request, *callback_args, **callback_kwargs)
  File "/taiga-back/taiga/users/views.py", line 16, in userinfo
    return render(request, 'user.tmpl', args)
  File "/home/taiga/.virtualenvs/taiga/lib/python3.4/site-packages/django/shortcuts.py", line 30, in render
    content = loader.render_to_string(template_name, context, request, using=using)
  File "/home/taiga/.virtualenvs/taiga/lib/python3.4/site-packages/django/template/loader.py", line 67, in render_to_string
    template = get_template(template_name, using=using)
  File "/home/taiga/.virtualenvs/taiga/lib/python3.4/site-packages/django/template/loader.py", line 25, in get_template
    raise TemplateDoesNotExist(template_name, chain=chain)
django.template.exceptions.TemplateDoesNotExist: user.tmpl
2017-05-15 14:25:55,016:basehttp "GET /user/1/ HTTP/1.1" 500 79571
2017-05-15 14:26:13,281:exception Internal Server Error: /user/1/
Traceback (most recent call last):
  File "/home/taiga/.virtualenvs/taiga/lib/python3.4/site-packages/django/core/handlers/exception.py", line 42, in inner
    response = get_response(request)
  File "/home/taiga/.virtualenvs/taiga/lib/python3.4/site-packages/django/core/handlers/base.py", line 187, in _get_response
    response = self.process_exception_by_middleware(e, request)
  File "/home/taiga/.virtualenvs/taiga/lib/python3.4/site-packages/django/core/handlers/base.py", line 185, in _get_response
    response = wrapped_callback(request, *callback_args, **callback_kwargs)
  File "/taiga-back/taiga/users/views.py", line 16, in userinfo
    return render(request, 'user.tmpl', args)
  File "/home/taiga/.virtualenvs/taiga/lib/python3.4/site-packages/django/shortcuts.py", line 30, in render
    content = loader.render_to_string(template_name, context, request, using=using)
  File "/home/taiga/.virtualenvs/taiga/lib/python3.4/site-packages/django/template/loader.py", line 67, in render_to_string
    template = get_template(template_name, using=using)
  File "/home/taiga/.virtualenvs/taiga/lib/python3.4/site-packages/django/template/loader.py", line 25, in get_template
    raise TemplateDoesNotExist(template_name, chain=chain)
django.template.exceptions.TemplateDoesNotExist: user.tmpl
2017-05-15 14:26:13,365:basehttp "GET /user/1/ HTTP/1.1" 500 79572
2017-05-15 14:26:44,806:exception Internal Server Error: /user/1/
Traceback (most recent call last):
  File "/home/taiga/.virtualenvs/taiga/lib/python3.4/site-packages/django/core/handlers/exception.py", line 42, in inner
    response = get_response(request)
  File "/home/taiga/.virtualenvs/taiga/lib/python3.4/site-packages/django/core/handlers/base.py", line 187, in _get_response
    response = self.process_exception_by_middleware(e, request)
  File "/home/taiga/.virtualenvs/taiga/lib/python3.4/site-packages/django/core/handlers/base.py", line 185, in _get_response
    response = wrapped_callback(request, *callback_args, **callback_kwargs)
  File "/taiga-back/taiga/users/views.py", line 16, in userinfo
    return render(request, 'user.tmpl', args)
  File "/home/taiga/.virtualenvs/taiga/lib/python3.4/site-packages/django/shortcuts.py", line 30, in render
    content = loader.render_to_string(template_name, context, request, using=using)
  File "/home/taiga/.virtualenvs/taiga/lib/python3.4/site-packages/django/template/loader.py", line 67, in render_to_string
    template = get_template(template_name, using=using)
  File "/home/taiga/.virtualenvs/taiga/lib/python3.4/site-packages/django/template/loader.py", line 25, in get_template
    raise TemplateDoesNotExist(template_name, chain=chain)
django.template.exceptions.TemplateDoesNotExist: user.tmpl
2017-05-15 14:26:44,911:basehttp "GET /user/1/ HTTP/1.1" 500 79524
2017-05-15 14:26:59,888:exception Internal Server Error: /user/1/
Traceback (most recent call last):
  File "/home/taiga/.virtualenvs/taiga/lib/python3.4/site-packages/django/core/handlers/exception.py", line 42, in inner
    response = get_response(request)
  File "/home/taiga/.virtualenvs/taiga/lib/python3.4/site-packages/django/core/handlers/base.py", line 187, in _get_response
    response = self.process_exception_by_middleware(e, request)
  File "/home/taiga/.virtualenvs/taiga/lib/python3.4/site-packages/django/core/handlers/base.py", line 185, in _get_response
    response = wrapped_callback(request, *callback_args, **callback_kwargs)
  File "/taiga-back/taiga/users/views.py", line 16, in userinfo
    return render(request, 'user.tmpl', args)
  File "/home/taiga/.virtualenvs/taiga/lib/python3.4/site-packages/django/shortcuts.py", line 30, in render
    content = loader.render_to_string(template_name, context, request, using=using)
  File "/home/taiga/.virtualenvs/taiga/lib/python3.4/site-packages/django/template/loader.py", line 67, in render_to_string
    template = get_template(template_name, using=using)
  File "/home/taiga/.virtualenvs/taiga/lib/python3.4/site-packages/django/template/loader.py", line 25, in get_template
    raise TemplateDoesNotExist(template_name, chain=chain)
django.template.exceptions.TemplateDoesNotExist: user.tmpl
2017-05-15 14:26:59,977:basehttp "GET /user/1/ HTTP/1.1" 500 79524
2017-05-15 14:27:22,784:exception Internal Server Error: /user/1/
Traceback (most recent call last):
  File "/home/taiga/.virtualenvs/taiga/lib/python3.4/site-packages/django/core/handlers/exception.py", line 42, in inner
    response = get_response(request)
  File "/home/taiga/.virtualenvs/taiga/lib/python3.4/site-packages/django/core/handlers/base.py", line 187, in _get_response
    response = self.process_exception_by_middleware(e, request)
  File "/home/taiga/.virtualenvs/taiga/lib/python3.4/site-packages/django/core/handlers/base.py", line 185, in _get_response
    response = wrapped_callback(request, *callback_args, **callback_kwargs)
  File "/taiga-back/taiga/users/views.py", line 16, in userinfo
    return render(request, 'user.tmpl', args)
  File "/home/taiga/.virtualenvs/taiga/lib/python3.4/site-packages/django/shortcuts.py", line 30, in render
    content = loader.render_to_string(template_name, context, request, using=using)
  File "/home/taiga/.virtualenvs/taiga/lib/python3.4/site-packages/django/template/loader.py", line 67, in render_to_string
    template = get_template(template_name, using=using)
  File "/home/taiga/.virtualenvs/taiga/lib/python3.4/site-packages/django/template/loader.py", line 25, in get_template
    raise TemplateDoesNotExist(template_name, chain=chain)
django.template.exceptions.TemplateDoesNotExist: user.tmpl
2017-05-15 14:27:22,864:basehttp "GET /user/1/ HTTP/1.1" 500 79524
2017-05-15 14:28:14,100:basehttp "GET /user/1/ HTTP/1.1" 200 8
2017-05-15 14:28:32,552:basehttp "GET /user/1/ HTTP/1.1" 200 8
2017-05-15 14:31:17,412:basehttp "GET /user/1/ HTTP/1.1" 200 22
2017-05-15 14:31:23,007:basehttp "GET /user/2/ HTTP/1.1" 200 22
2017-05-15 14:31:26,911:basehttp "GET /user/3/ HTTP/1.1" 200 22
2017-05-15 14:31:41,788:basehttp "GET /user/3/ HTTP/1.1" 200 29
2017-05-15 14:31:48,212:basehttp "GET /user/3/ HTTP/1.1" 200 29
2017-05-15 14:31:52,143:basehttp "GET /user/3/ HTTP/1.1" 200 29
2017-05-15 14:32:31,189:exception Internal Server Error: /user/3/
Traceback (most recent call last):
  File "/home/taiga/.virtualenvs/taiga/lib/python3.4/site-packages/django/core/handlers/exception.py", line 42, in inner
    response = get_response(request)
  File "/home/taiga/.virtualenvs/taiga/lib/python3.4/site-packages/django/core/handlers/base.py", line 187, in _get_response
    response = self.process_exception_by_middleware(e, request)
  File "/home/taiga/.virtualenvs/taiga/lib/python3.4/site-packages/django/core/handlers/base.py", line 185, in _get_response
    response = wrapped_callback(request, *callback_args, **callback_kwargs)
  File "/taiga-back/taiga/users/views.py", line 16, in userinfo
    return render(request, 'user.tmpl', user)
  File "/home/taiga/.virtualenvs/taiga/lib/python3.4/site-packages/django/shortcuts.py", line 30, in render
    content = loader.render_to_string(template_name, context, request, using=using)
  File "/home/taiga/.virtualenvs/taiga/lib/python3.4/site-packages/django/template/loader.py", line 68, in render_to_string
    return template.render(context, request)
  File "/home/taiga/.virtualenvs/taiga/lib/python3.4/site-packages/django/template/backends/django.py", line 64, in render
    context = make_context(context, request, autoescape=self.backend.engine.autoescape)
  File "/home/taiga/.virtualenvs/taiga/lib/python3.4/site-packages/django/template/context.py", line 267, in make_context
    context.push(original_context)
  File "/home/taiga/.virtualenvs/taiga/lib/python3.4/site-packages/django/template/context.py", line 59, in push
    return ContextDict(self, *dicts, **kwargs)
  File "/home/taiga/.virtualenvs/taiga/lib/python3.4/site-packages/django/template/context.py", line 18, in __init__
    super(ContextDict, self).__init__(*args, **kwargs)
TypeError: 'User' object is not iterable
2017-05-15 14:32:31,274:basehttp "GET /user/3/ HTTP/1.1" 500 89446
2017-05-15 14:33:28,629:exception Internal Server Error: /user/3/
Traceback (most recent call last):
  File "/home/taiga/.virtualenvs/taiga/lib/python3.4/site-packages/django/core/handlers/exception.py", line 42, in inner
    response = get_response(request)
  File "/home/taiga/.virtualenvs/taiga/lib/python3.4/site-packages/django/core/handlers/base.py", line 187, in _get_response
    response = self.process_exception_by_middleware(e, request)
  File "/home/taiga/.virtualenvs/taiga/lib/python3.4/site-packages/django/core/handlers/base.py", line 185, in _get_response
    response = wrapped_callback(request, *callback_args, **callback_kwargs)
  File "/taiga-back/taiga/users/views.py", line 17, in userinfo
    return render(request, 'user.tmpl', user)
  File "/home/taiga/.virtualenvs/taiga/lib/python3.4/site-packages/django/shortcuts.py", line 30, in render
    content = loader.render_to_string(template_name, context, request, using=using)
  File "/home/taiga/.virtualenvs/taiga/lib/python3.4/site-packages/django/template/loader.py", line 68, in render_to_string
    return template.render(context, request)
  File "/home/taiga/.virtualenvs/taiga/lib/python3.4/site-packages/django/template/backends/django.py", line 64, in render
    context = make_context(context, request, autoescape=self.backend.engine.autoescape)
  File "/home/taiga/.virtualenvs/taiga/lib/python3.4/site-packages/django/template/context.py", line 267, in make_context
    context.push(original_context)
  File "/home/taiga/.virtualenvs/taiga/lib/python3.4/site-packages/django/template/context.py", line 59, in push
    return ContextDict(self, *dicts, **kwargs)
  File "/home/taiga/.virtualenvs/taiga/lib/python3.4/site-packages/django/template/context.py", line 18, in __init__
    super(ContextDict, self).__init__(*args, **kwargs)
TypeError: 'User' object is not iterable
2017-05-15 14:33:28,734:basehttp "GET /user/3/ HTTP/1.1" 500 89519
2017-05-15 14:33:44,860:basehttp "GET /user/3/ HTTP/1.1" 200 46
2017-05-15 14:34:17,026:basehttp "GET /user/3/ HTTP/1.1" 200 43
2017-05-15 14:34:22,462:basehttp "GET /user/3/ HTTP/1.1" 200 36
2017-05-15 14:34:43,023:exception Internal Server Error: /user/3/
Traceback (most recent call last):
  File "/home/taiga/.virtualenvs/taiga/lib/python3.4/site-packages/django/core/handlers/exception.py", line 42, in inner
    response = get_response(request)
  File "/home/taiga/.virtualenvs/taiga/lib/python3.4/site-packages/django/core/handlers/base.py", line 187, in _get_response
    response = self.process_exception_by_middleware(e, request)
  File "/home/taiga/.virtualenvs/taiga/lib/python3.4/site-packages/django/core/handlers/base.py", line 185, in _get_response
    response = wrapped_callback(request, *callback_args, **callback_kwargs)
  File "/taiga-back/taiga/users/views.py", line 17, in userinfo
    return render(request, 'user.tmpl', user)
  File "/home/taiga/.virtualenvs/taiga/lib/python3.4/site-packages/django/shortcuts.py", line 30, in render
    content = loader.render_to_string(template_name, context, request, using=using)
  File "/home/taiga/.virtualenvs/taiga/lib/python3.4/site-packages/django/template/loader.py", line 68, in render_to_string
    return template.render(context, request)
  File "/home/taiga/.virtualenvs/taiga/lib/python3.4/site-packages/django/template/backends/django.py", line 64, in render
    context = make_context(context, request, autoescape=self.backend.engine.autoescape)
  File "/home/taiga/.virtualenvs/taiga/lib/python3.4/site-packages/django/template/context.py", line 267, in make_context
    context.push(original_context)
  File "/home/taiga/.virtualenvs/taiga/lib/python3.4/site-packages/django/template/context.py", line 59, in push
    return ContextDict(self, *dicts, **kwargs)
  File "/home/taiga/.virtualenvs/taiga/lib/python3.4/site-packages/django/template/context.py", line 18, in __init__
    super(ContextDict, self).__init__(*args, **kwargs)
TypeError: 'User' object is not iterable
2017-05-15 14:34:43,118:basehttp "GET /user/3/ HTTP/1.1" 500 89519
2017-05-15 14:35:07,927:basehttp "GET /user/3/ HTTP/1.1" 200 36
2017-05-15 14:40:13,771:basehttp "GET /user/3/ HTTP/1.1" 200 46
2017-05-15 14:40:18,062:basehttp "GET /user/ HTTP/1.1" 404 2112
2017-05-15 14:40:55,576:basehttp "GET /user/ HTTP/1.1" 404 2115
2017-05-15 14:46:23,458:basehttp "GET /user/1/ HTTP/1.1" 200 0
2017-05-15 14:46:27,892:exception Internal Server Error: /user/
Traceback (most recent call last):
  File "/home/taiga/.virtualenvs/taiga/lib/python3.4/site-packages/django/core/handlers/exception.py", line 42, in inner
    response = get_response(request)
  File "/home/taiga/.virtualenvs/taiga/lib/python3.4/site-packages/django/core/handlers/base.py", line 187, in _get_response
    response = self.process_exception_by_middleware(e, request)
  File "/home/taiga/.virtualenvs/taiga/lib/python3.4/site-packages/django/core/handlers/base.py", line 185, in _get_response
    response = wrapped_callback(request, *callback_args, **callback_kwargs)
  File "/taiga-back/taiga/users/views.py", line 8, in users_list
    return render(request, 'users_list.tmpl', users)
  File "/home/taiga/.virtualenvs/taiga/lib/python3.4/site-packages/django/shortcuts.py", line 30, in render
    content = loader.render_to_string(template_name, context, request, using=using)
  File "/home/taiga/.virtualenvs/taiga/lib/python3.4/site-packages/django/template/loader.py", line 67, in render_to_string
    template = get_template(template_name, using=using)
  File "/home/taiga/.virtualenvs/taiga/lib/python3.4/site-packages/django/template/loader.py", line 25, in get_template
    raise TemplateDoesNotExist(template_name, chain=chain)
django.template.exceptions.TemplateDoesNotExist: users_list.tmpl
2017-05-15 14:46:27,978:basehttp "GET /user/ HTTP/1.1" 500 79735
2017-05-15 14:47:09,163:exception Internal Server Error: /user/
Traceback (most recent call last):
  File "/home/taiga/.virtualenvs/taiga/lib/python3.4/site-packages/django/core/handlers/exception.py", line 42, in inner
    response = get_response(request)
  File "/home/taiga/.virtualenvs/taiga/lib/python3.4/site-packages/django/core/handlers/base.py", line 187, in _get_response
    response = self.process_exception_by_middleware(e, request)
  File "/home/taiga/.virtualenvs/taiga/lib/python3.4/site-packages/django/core/handlers/base.py", line 185, in _get_response
    response = wrapped_callback(request, *callback_args, **callback_kwargs)
  File "/taiga-back/taiga/users/views.py", line 8, in users_list
    return render(request, 'users_list.tmpl', users)
  File "/home/taiga/.virtualenvs/taiga/lib/python3.4/site-packages/django/shortcuts.py", line 30, in render
    content = loader.render_to_string(template_name, context, request, using=using)
  File "/home/taiga/.virtualenvs/taiga/lib/python3.4/site-packages/django/template/loader.py", line 67, in render_to_string
    template = get_template(template_name, using=using)
  File "/home/taiga/.virtualenvs/taiga/lib/python3.4/site-packages/django/template/loader.py", line 25, in get_template
    raise TemplateDoesNotExist(template_name, chain=chain)
django.template.exceptions.TemplateDoesNotExist: users_list.tmpl
2017-05-15 14:47:09,264:basehttp "GET /user/ HTTP/1.1" 500 79870
2017-05-15 14:47:11,537:basehttp "GET /user/1/ HTTP/1.1" 200 0
2017-05-15 14:47:13,288:basehttp "GET /user/1/ HTTP/1.1" 200 0
2017-05-15 14:48:00,105:basehttp "GET /user/1/ HTTP/1.1" 200 46
2017-05-15 14:48:04,153:basehttp "GET /user HTTP/1.1" 301 0
2017-05-15 14:48:04,164:exception Internal Server Error: /user/
Traceback (most recent call last):
  File "/home/taiga/.virtualenvs/taiga/lib/python3.4/site-packages/django/core/handlers/exception.py", line 42, in inner
    response = get_response(request)
  File "/home/taiga/.virtualenvs/taiga/lib/python3.4/site-packages/django/core/handlers/base.py", line 187, in _get_response
    response = self.process_exception_by_middleware(e, request)
  File "/home/taiga/.virtualenvs/taiga/lib/python3.4/site-packages/django/core/handlers/base.py", line 185, in _get_response
    response = wrapped_callback(request, *callback_args, **callback_kwargs)
  File "/taiga-back/taiga/users/views.py", line 8, in users_list
    return render(request, 'users_list.tmpl', users)
  File "/home/taiga/.virtualenvs/taiga/lib/python3.4/site-packages/django/shortcuts.py", line 30, in render
    content = loader.render_to_string(template_name, context, request, using=using)
  File "/home/taiga/.virtualenvs/taiga/lib/python3.4/site-packages/django/template/loader.py", line 67, in render_to_string
    template = get_template(template_name, using=using)
  File "/home/taiga/.virtualenvs/taiga/lib/python3.4/site-packages/django/template/loader.py", line 25, in get_template
    raise TemplateDoesNotExist(template_name, chain=chain)
django.template.exceptions.TemplateDoesNotExist: users_list.tmpl
2017-05-15 14:48:04,271:basehttp "GET /user/ HTTP/1.1" 500 79735
2017-05-15 14:48:06,236:exception Internal Server Error: /user/
Traceback (most recent call last):
  File "/home/taiga/.virtualenvs/taiga/lib/python3.4/site-packages/django/core/handlers/exception.py", line 42, in inner
    response = get_response(request)
  File "/home/taiga/.virtualenvs/taiga/lib/python3.4/site-packages/django/core/handlers/base.py", line 187, in _get_response
    response = self.process_exception_by_middleware(e, request)
  File "/home/taiga/.virtualenvs/taiga/lib/python3.4/site-packages/django/core/handlers/base.py", line 185, in _get_response
    response = wrapped_callback(request, *callback_args, **callback_kwargs)
  File "/taiga-back/taiga/users/views.py", line 8, in users_list
    return render(request, 'users_list.tmpl', users)
  File "/home/taiga/.virtualenvs/taiga/lib/python3.4/site-packages/django/shortcuts.py", line 30, in render
    content = loader.render_to_string(template_name, context, request, using=using)
  File "/home/taiga/.virtualenvs/taiga/lib/python3.4/site-packages/django/template/loader.py", line 67, in render_to_string
    template = get_template(template_name, using=using)
  File "/home/taiga/.virtualenvs/taiga/lib/python3.4/site-packages/django/template/loader.py", line 25, in get_template
    raise TemplateDoesNotExist(template_name, chain=chain)
django.template.exceptions.TemplateDoesNotExist: users_list.tmpl
2017-05-15 14:48:06,335:basehttp "GET /user/ HTTP/1.1" 500 79870
2017-05-15 14:48:57,848:exception Internal Server Error: /user/
Traceback (most recent call last):
  File "/home/taiga/.virtualenvs/taiga/lib/python3.4/site-packages/django/core/handlers/exception.py", line 42, in inner
    response = get_response(request)
  File "/home/taiga/.virtualenvs/taiga/lib/python3.4/site-packages/django/core/handlers/base.py", line 187, in _get_response
    response = self.process_exception_by_middleware(e, request)
  File "/home/taiga/.virtualenvs/taiga/lib/python3.4/site-packages/django/core/handlers/base.py", line 185, in _get_response
    response = wrapped_callback(request, *callback_args, **callback_kwargs)
  File "/taiga-back/taiga/users/views.py", line 8, in users_list
    return render(request, 'users_list.tmpl', users)
  File "/home/taiga/.virtualenvs/taiga/lib/python3.4/site-packages/django/shortcuts.py", line 30, in render
    content = loader.render_to_string(template_name, context, request, using=using)
  File "/home/taiga/.virtualenvs/taiga/lib/python3.4/site-packages/django/template/loader.py", line 68, in render_to_string
    return template.render(context, request)
  File "/home/taiga/.virtualenvs/taiga/lib/python3.4/site-packages/django/template/backends/django.py", line 64, in render
    context = make_context(context, request, autoescape=self.backend.engine.autoescape)
  File "/home/taiga/.virtualenvs/taiga/lib/python3.4/site-packages/django/template/context.py", line 267, in make_context
    context.push(original_context)
  File "/home/taiga/.virtualenvs/taiga/lib/python3.4/site-packages/django/template/context.py", line 59, in push
    return ContextDict(self, *dicts, **kwargs)
  File "/home/taiga/.virtualenvs/taiga/lib/python3.4/site-packages/django/template/context.py", line 18, in __init__
    super(ContextDict, self).__init__(*args, **kwargs)
TypeError: cannot convert dictionary update sequence element #0 to a sequence
2017-05-15 14:48:57,937:basehttp "GET /user/ HTTP/1.1" 500 90689
2017-05-15 14:48:58,935:exception Internal Server Error: /user/
Traceback (most recent call last):
  File "/home/taiga/.virtualenvs/taiga/lib/python3.4/site-packages/django/core/handlers/exception.py", line 42, in inner
    response = get_response(request)
  File "/home/taiga/.virtualenvs/taiga/lib/python3.4/site-packages/django/core/handlers/base.py", line 187, in _get_response
    response = self.process_exception_by_middleware(e, request)
  File "/home/taiga/.virtualenvs/taiga/lib/python3.4/site-packages/django/core/handlers/base.py", line 185, in _get_response
    response = wrapped_callback(request, *callback_args, **callback_kwargs)
  File "/taiga-back/taiga/users/views.py", line 8, in users_list
    return render(request, 'users_list.tmpl', users)
  File "/home/taiga/.virtualenvs/taiga/lib/python3.4/site-packages/django/shortcuts.py", line 30, in render
    content = loader.render_to_string(template_name, context, request, using=using)
  File "/home/taiga/.virtualenvs/taiga/lib/python3.4/site-packages/django/template/loader.py", line 68, in render_to_string
    return template.render(context, request)
  File "/home/taiga/.virtualenvs/taiga/lib/python3.4/site-packages/django/template/backends/django.py", line 64, in render
    context = make_context(context, request, autoescape=self.backend.engine.autoescape)
  File "/home/taiga/.virtualenvs/taiga/lib/python3.4/site-packages/django/template/context.py", line 267, in make_context
    context.push(original_context)
  File "/home/taiga/.virtualenvs/taiga/lib/python3.4/site-packages/django/template/context.py", line 59, in push
    return ContextDict(self, *dicts, **kwargs)
  File "/home/taiga/.virtualenvs/taiga/lib/python3.4/site-packages/django/template/context.py", line 18, in __init__
    super(ContextDict, self).__init__(*args, **kwargs)
TypeError: cannot convert dictionary update sequence element #0 to a sequence
2017-05-15 14:48:59,019:basehttp "GET /user/ HTTP/1.1" 500 90689
2017-05-15 14:49:22,486:exception Internal Server Error: /user/
Traceback (most recent call last):
  File "/home/taiga/.virtualenvs/taiga/lib/python3.4/site-packages/django/core/handlers/exception.py", line 42, in inner
    response = get_response(request)
  File "/home/taiga/.virtualenvs/taiga/lib/python3.4/site-packages/django/core/handlers/base.py", line 187, in _get_response
    response = self.process_exception_by_middleware(e, request)
  File "/home/taiga/.virtualenvs/taiga/lib/python3.4/site-packages/django/core/handlers/base.py", line 185, in _get_response
    response = wrapped_callback(request, *callback_args, **callback_kwargs)
  File "/taiga-back/taiga/users/views.py", line 7, in users_list
    users = dict(User.objects.all())
TypeError: cannot convert dictionary update sequence element #0 to a sequence
2017-05-15 14:49:22,612:basehttp "GET /user/ HTTP/1.1" 500 64529
2017-05-15 14:49:50,196:exception Internal Server Error: /user/
Traceback (most recent call last):
  File "/home/taiga/.virtualenvs/taiga/lib/python3.4/site-packages/django/core/handlers/exception.py", line 42, in inner
    response = get_response(request)
  File "/home/taiga/.virtualenvs/taiga/lib/python3.4/site-packages/django/core/handlers/base.py", line 187, in _get_response
    response = self.process_exception_by_middleware(e, request)
  File "/home/taiga/.virtualenvs/taiga/lib/python3.4/site-packages/django/core/handlers/base.py", line 185, in _get_response
    response = wrapped_callback(request, *callback_args, **callback_kwargs)
  File "/taiga-back/taiga/users/views.py", line 8, in users_list
    return render(request, 'users_list.tmpl', users)
  File "/home/taiga/.virtualenvs/taiga/lib/python3.4/site-packages/django/shortcuts.py", line 30, in render
    content = loader.render_to_string(template_name, context, request, using=using)
  File "/home/taiga/.virtualenvs/taiga/lib/python3.4/site-packages/django/template/loader.py", line 67, in render_to_string
    template = get_template(template_name, using=using)
  File "/home/taiga/.virtualenvs/taiga/lib/python3.4/site-packages/django/template/loader.py", line 21, in get_template
    return engine.get_template(template_name)
  File "/home/taiga/.virtualenvs/taiga/lib/python3.4/site-packages/django/template/backends/django.py", line 39, in get_template
    return Template(self.engine.get_template(template_name), self)
  File "/home/taiga/.virtualenvs/taiga/lib/python3.4/site-packages/django/template/engine.py", line 160, in get_template
    template, origin = self.find_template(template_name)
  File "/home/taiga/.virtualenvs/taiga/lib/python3.4/site-packages/django/template/engine.py", line 134, in find_template
    name, template_dirs=dirs, skip=skip,
  File "/home/taiga/.virtualenvs/taiga/lib/python3.4/site-packages/django/template/loaders/base.py", line 44, in get_template
    contents, origin, origin.template_name, self.engine,
  File "/home/taiga/.virtualenvs/taiga/lib/python3.4/site-packages/django/template/base.py", line 191, in __init__
    self.nodelist = self.compile_nodelist()
  File "/home/taiga/.virtualenvs/taiga/lib/python3.4/site-packages/django/template/base.py", line 233, in compile_nodelist
    return parser.parse()
  File "/home/taiga/.virtualenvs/taiga/lib/python3.4/site-packages/django/template/base.py", line 518, in parse
    raise self.error(token, e)
  File "/home/taiga/.virtualenvs/taiga/lib/python3.4/site-packages/django/template/base.py", line 516, in parse
    compiled_result = compile_func(self, token)
  File "/home/taiga/.virtualenvs/taiga/lib/python3.4/site-packages/django/template/defaulttags.py", line 802, in do_for
    sequence = parser.compile_filter(bits[in_index + 1])
  File "/home/taiga/.virtualenvs/taiga/lib/python3.4/site-packages/django/template/base.py", line 603, in compile_filter
    return FilterExpression(token, self)
  File "/home/taiga/.virtualenvs/taiga/lib/python3.4/site-packages/django/template/base.py", line 703, in __init__
    "from '%s'" % (token[upto:], token))
django.template.exceptions.TemplateSyntaxError: Could not parse the remainder: '()' from 'users.items()'
2017-05-15 14:49:50,312:basehttp "GET /user/ HTTP/1.1" 500 130376
2017-05-15 14:49:56,736:exception Internal Server Error: /user/
Traceback (most recent call last):
  File "/home/taiga/.virtualenvs/taiga/lib/python3.4/site-packages/django/core/handlers/exception.py", line 42, in inner
    response = get_response(request)
  File "/home/taiga/.virtualenvs/taiga/lib/python3.4/site-packages/django/core/handlers/base.py", line 187, in _get_response
    response = self.process_exception_by_middleware(e, request)
  File "/home/taiga/.virtualenvs/taiga/lib/python3.4/site-packages/django/core/handlers/base.py", line 185, in _get_response
    response = wrapped_callback(request, *callback_args, **callback_kwargs)
  File "/taiga-back/taiga/users/views.py", line 8, in users_list
    return render(request, 'users_list.tmpl', users)
  File "/home/taiga/.virtualenvs/taiga/lib/python3.4/site-packages/django/shortcuts.py", line 30, in render
    content = loader.render_to_string(template_name, context, request, using=using)
  File "/home/taiga/.virtualenvs/taiga/lib/python3.4/site-packages/django/template/loader.py", line 68, in render_to_string
    return template.render(context, request)
  File "/home/taiga/.virtualenvs/taiga/lib/python3.4/site-packages/django/template/backends/django.py", line 64, in render
    context = make_context(context, request, autoescape=self.backend.engine.autoescape)
  File "/home/taiga/.virtualenvs/taiga/lib/python3.4/site-packages/django/template/context.py", line 267, in make_context
    context.push(original_context)
  File "/home/taiga/.virtualenvs/taiga/lib/python3.4/site-packages/django/template/context.py", line 59, in push
    return ContextDict(self, *dicts, **kwargs)
  File "/home/taiga/.virtualenvs/taiga/lib/python3.4/site-packages/django/template/context.py", line 18, in __init__
    super(ContextDict, self).__init__(*args, **kwargs)
TypeError: cannot convert dictionary update sequence element #0 to a sequence
2017-05-15 14:49:56,819:basehttp "GET /user/ HTTP/1.1" 500 90689
2017-05-15 14:51:16,494:exception Internal Server Error: /user/
Traceback (most recent call last):
  File "/home/taiga/.virtualenvs/taiga/lib/python3.4/site-packages/django/core/handlers/exception.py", line 42, in inner
    response = get_response(request)
  File "/home/taiga/.virtualenvs/taiga/lib/python3.4/site-packages/django/core/handlers/base.py", line 187, in _get_response
    response = self.process_exception_by_middleware(e, request)
  File "/home/taiga/.virtualenvs/taiga/lib/python3.4/site-packages/django/core/handlers/base.py", line 185, in _get_response
    response = wrapped_callback(request, *callback_args, **callback_kwargs)
  File "/taiga-back/taiga/users/views.py", line 8, in users_list
    return render(request, 'users_list.tmpl', users)
  File "/home/taiga/.virtualenvs/taiga/lib/python3.4/site-packages/django/shortcuts.py", line 30, in render
    content = loader.render_to_string(template_name, context, request, using=using)
  File "/home/taiga/.virtualenvs/taiga/lib/python3.4/site-packages/django/template/loader.py", line 68, in render_to_string
    return template.render(context, request)
  File "/home/taiga/.virtualenvs/taiga/lib/python3.4/site-packages/django/template/backends/django.py", line 64, in render
    context = make_context(context, request, autoescape=self.backend.engine.autoescape)
  File "/home/taiga/.virtualenvs/taiga/lib/python3.4/site-packages/django/template/context.py", line 267, in make_context
    context.push(original_context)
  File "/home/taiga/.virtualenvs/taiga/lib/python3.4/site-packages/django/template/context.py", line 59, in push
    return ContextDict(self, *dicts, **kwargs)
  File "/home/taiga/.virtualenvs/taiga/lib/python3.4/site-packages/django/template/context.py", line 18, in __init__
    super(ContextDict, self).__init__(*args, **kwargs)
TypeError: cannot convert dictionary update sequence element #0 to a sequence
2017-05-15 14:51:16,613:basehttp "GET /user/ HTTP/1.1" 500 90689
2017-05-15 14:51:17,712:exception Internal Server Error: /user/
Traceback (most recent call last):
  File "/home/taiga/.virtualenvs/taiga/lib/python3.4/site-packages/django/core/handlers/exception.py", line 42, in inner
    response = get_response(request)
  File "/home/taiga/.virtualenvs/taiga/lib/python3.4/site-packages/django/core/handlers/base.py", line 187, in _get_response
    response = self.process_exception_by_middleware(e, request)
  File "/home/taiga/.virtualenvs/taiga/lib/python3.4/site-packages/django/core/handlers/base.py", line 185, in _get_response
    response = wrapped_callback(request, *callback_args, **callback_kwargs)
  File "/taiga-back/taiga/users/views.py", line 8, in users_list
    return render(request, 'users_list.tmpl', users)
  File "/home/taiga/.virtualenvs/taiga/lib/python3.4/site-packages/django/shortcuts.py", line 30, in render
    content = loader.render_to_string(template_name, context, request, using=using)
  File "/home/taiga/.virtualenvs/taiga/lib/python3.4/site-packages/django/template/loader.py", line 68, in render_to_string
    return template.render(context, request)
  File "/home/taiga/.virtualenvs/taiga/lib/python3.4/site-packages/django/template/backends/django.py", line 64, in render
    context = make_context(context, request, autoescape=self.backend.engine.autoescape)
  File "/home/taiga/.virtualenvs/taiga/lib/python3.4/site-packages/django/template/context.py", line 267, in make_context
    context.push(original_context)
  File "/home/taiga/.virtualenvs/taiga/lib/python3.4/site-packages/django/template/context.py", line 59, in push
    return ContextDict(self, *dicts, **kwargs)
  File "/home/taiga/.virtualenvs/taiga/lib/python3.4/site-packages/django/template/context.py", line 18, in __init__
    super(ContextDict, self).__init__(*args, **kwargs)
TypeError: cannot convert dictionary update sequence element #0 to a sequence
2017-05-15 14:51:17,795:basehttp "GET /user/ HTTP/1.1" 500 90689
2017-05-15 14:51:37,114:exception Internal Server Error: /user/
Traceback (most recent call last):
  File "/home/taiga/.virtualenvs/taiga/lib/python3.4/site-packages/django/core/handlers/exception.py", line 42, in inner
    response = get_response(request)
  File "/home/taiga/.virtualenvs/taiga/lib/python3.4/site-packages/django/core/handlers/base.py", line 187, in _get_response
    response = self.process_exception_by_middleware(e, request)
  File "/home/taiga/.virtualenvs/taiga/lib/python3.4/site-packages/django/core/handlers/base.py", line 185, in _get_response
    response = wrapped_callback(request, *callback_args, **callback_kwargs)
  File "/taiga-back/taiga/users/views.py", line 8, in users_list
    return render(request, 'users_list.tmpl', users)
  File "/home/taiga/.virtualenvs/taiga/lib/python3.4/site-packages/django/shortcuts.py", line 30, in render
    content = loader.render_to_string(template_name, context, request, using=using)
  File "/home/taiga/.virtualenvs/taiga/lib/python3.4/site-packages/django/template/loader.py", line 68, in render_to_string
    return template.render(context, request)
  File "/home/taiga/.virtualenvs/taiga/lib/python3.4/site-packages/django/template/backends/django.py", line 64, in render
    context = make_context(context, request, autoescape=self.backend.engine.autoescape)
  File "/home/taiga/.virtualenvs/taiga/lib/python3.4/site-packages/django/template/context.py", line 267, in make_context
    context.push(original_context)
  File "/home/taiga/.virtualenvs/taiga/lib/python3.4/site-packages/django/template/context.py", line 59, in push
    return ContextDict(self, *dicts, **kwargs)
  File "/home/taiga/.virtualenvs/taiga/lib/python3.4/site-packages/django/template/context.py", line 18, in __init__
    super(ContextDict, self).__init__(*args, **kwargs)
TypeError: cannot convert dictionary update sequence element #0 to a sequence
2017-05-15 14:51:37,248:basehttp "GET /user/ HTTP/1.1" 500 90542
2017-05-15 14:51:45,764:exception Internal Server Error: /user/
Traceback (most recent call last):
  File "/home/taiga/.virtualenvs/taiga/lib/python3.4/site-packages/django/core/handlers/exception.py", line 42, in inner
    response = get_response(request)
  File "/home/taiga/.virtualenvs/taiga/lib/python3.4/site-packages/django/core/handlers/base.py", line 187, in _get_response
    response = self.process_exception_by_middleware(e, request)
  File "/home/taiga/.virtualenvs/taiga/lib/python3.4/site-packages/django/core/handlers/base.py", line 185, in _get_response
    response = wrapped_callback(request, *callback_args, **callback_kwargs)
  File "/taiga-back/taiga/users/views.py", line 7, in users_list
    users = lis(User.objects.all())
NameError: name 'lis' is not defined
2017-05-15 14:51:45,840:basehttp "GET /user/ HTTP/1.1" 500 64397
2017-05-15 14:53:57,339:exception Internal Server Error: /user/
Traceback (most recent call last):
  File "/home/taiga/.virtualenvs/taiga/lib/python3.4/site-packages/django/core/handlers/exception.py", line 42, in inner
    response = get_response(request)
  File "/home/taiga/.virtualenvs/taiga/lib/python3.4/site-packages/django/core/handlers/base.py", line 187, in _get_response
    response = self.process_exception_by_middleware(e, request)
  File "/home/taiga/.virtualenvs/taiga/lib/python3.4/site-packages/django/core/handlers/base.py", line 185, in _get_response
    response = wrapped_callback(request, *callback_args, **callback_kwargs)
  File "/taiga-back/taiga/users/views.py", line 8, in users_list
    return render(request, 'users_list.tmpl', users)
  File "/home/taiga/.virtualenvs/taiga/lib/python3.4/site-packages/django/shortcuts.py", line 30, in render
    content = loader.render_to_string(template_name, context, request, using=using)
  File "/home/taiga/.virtualenvs/taiga/lib/python3.4/site-packages/django/template/loader.py", line 68, in render_to_string
    return template.render(context, request)
  File "/home/taiga/.virtualenvs/taiga/lib/python3.4/site-packages/django/template/backends/django.py", line 64, in render
    context = make_context(context, request, autoescape=self.backend.engine.autoescape)
  File "/home/taiga/.virtualenvs/taiga/lib/python3.4/site-packages/django/template/context.py", line 267, in make_context
    context.push(original_context)
  File "/home/taiga/.virtualenvs/taiga/lib/python3.4/site-packages/django/template/context.py", line 59, in push
    return ContextDict(self, *dicts, **kwargs)
  File "/home/taiga/.virtualenvs/taiga/lib/python3.4/site-packages/django/template/context.py", line 18, in __init__
    super(ContextDict, self).__init__(*args, **kwargs)
ValueError: dictionary update sequence element #0 has length 6; 2 is required
2017-05-15 14:53:57,421:basehttp "GET /user/ HTTP/1.1" 500 95356
2017-05-15 14:55:37,681:exception Internal Server Error: /user/
Traceback (most recent call last):
  File "/home/taiga/.virtualenvs/taiga/lib/python3.4/site-packages/django/core/handlers/exception.py", line 42, in inner
    response = get_response(request)
  File "/home/taiga/.virtualenvs/taiga/lib/python3.4/site-packages/django/core/handlers/base.py", line 187, in _get_response
    response = self.process_exception_by_middleware(e, request)
  File "/home/taiga/.virtualenvs/taiga/lib/python3.4/site-packages/django/core/handlers/base.py", line 185, in _get_response
    response = wrapped_callback(request, *callback_args, **callback_kwargs)
  File "/taiga-back/taiga/users/views.py", line 8, in users_list
    return render(request, 'users_list.tmpl', users)
  File "/home/taiga/.virtualenvs/taiga/lib/python3.4/site-packages/django/shortcuts.py", line 30, in render
    content = loader.render_to_string(template_name, context, request, using=using)
  File "/home/taiga/.virtualenvs/taiga/lib/python3.4/site-packages/django/template/loader.py", line 68, in render_to_string
    return template.render(context, request)
  File "/home/taiga/.virtualenvs/taiga/lib/python3.4/site-packages/django/template/backends/django.py", line 64, in render
    context = make_context(context, request, autoescape=self.backend.engine.autoescape)
  File "/home/taiga/.virtualenvs/taiga/lib/python3.4/site-packages/django/template/context.py", line 267, in make_context
    context.push(original_context)
  File "/home/taiga/.virtualenvs/taiga/lib/python3.4/site-packages/django/template/context.py", line 59, in push
    return ContextDict(self, *dicts, **kwargs)
  File "/home/taiga/.virtualenvs/taiga/lib/python3.4/site-packages/django/template/context.py", line 18, in __init__
    super(ContextDict, self).__init__(*args, **kwargs)
ValueError: dictionary update sequence element #0 has length 6; 2 is required
2017-05-15 14:55:37,766:basehttp "GET /user/ HTTP/1.1" 500 95356
2017-05-15 14:55:38,446:exception Internal Server Error: /user/
Traceback (most recent call last):
  File "/home/taiga/.virtualenvs/taiga/lib/python3.4/site-packages/django/core/handlers/exception.py", line 42, in inner
    response = get_response(request)
  File "/home/taiga/.virtualenvs/taiga/lib/python3.4/site-packages/django/core/handlers/base.py", line 187, in _get_response
    response = self.process_exception_by_middleware(e, request)
  File "/home/taiga/.virtualenvs/taiga/lib/python3.4/site-packages/django/core/handlers/base.py", line 185, in _get_response
    response = wrapped_callback(request, *callback_args, **callback_kwargs)
  File "/taiga-back/taiga/users/views.py", line 8, in users_list
    return render(request, 'users_list.tmpl', users)
  File "/home/taiga/.virtualenvs/taiga/lib/python3.4/site-packages/django/shortcuts.py", line 30, in render
    content = loader.render_to_string(template_name, context, request, using=using)
  File "/home/taiga/.virtualenvs/taiga/lib/python3.4/site-packages/django/template/loader.py", line 68, in render_to_string
    return template.render(context, request)
  File "/home/taiga/.virtualenvs/taiga/lib/python3.4/site-packages/django/template/backends/django.py", line 64, in render
    context = make_context(context, request, autoescape=self.backend.engine.autoescape)
  File "/home/taiga/.virtualenvs/taiga/lib/python3.4/site-packages/django/template/context.py", line 267, in make_context
    context.push(original_context)
  File "/home/taiga/.virtualenvs/taiga/lib/python3.4/site-packages/django/template/context.py", line 59, in push
    return ContextDict(self, *dicts, **kwargs)
  File "/home/taiga/.virtualenvs/taiga/lib/python3.4/site-packages/django/template/context.py", line 18, in __init__
    super(ContextDict, self).__init__(*args, **kwargs)
ValueError: dictionary update sequence element #0 has length 6; 2 is required
2017-05-15 14:55:38,582:basehttp "GET /user/ HTTP/1.1" 500 95356
2017-05-15 14:55:41,070:exception Internal Server Error: /user/
Traceback (most recent call last):
  File "/home/taiga/.virtualenvs/taiga/lib/python3.4/site-packages/django/core/handlers/exception.py", line 42, in inner
    response = get_response(request)
  File "/home/taiga/.virtualenvs/taiga/lib/python3.4/site-packages/django/core/handlers/base.py", line 187, in _get_response
    response = self.process_exception_by_middleware(e, request)
  File "/home/taiga/.virtualenvs/taiga/lib/python3.4/site-packages/django/core/handlers/base.py", line 185, in _get_response
    response = wrapped_callback(request, *callback_args, **callback_kwargs)
  File "/taiga-back/taiga/users/views.py", line 8, in users_list
    return render(request, 'users_list.tmpl', users)
  File "/home/taiga/.virtualenvs/taiga/lib/python3.4/site-packages/django/shortcuts.py", line 30, in render
    content = loader.render_to_string(template_name, context, request, using=using)
  File "/home/taiga/.virtualenvs/taiga/lib/python3.4/site-packages/django/template/loader.py", line 68, in render_to_string
    return template.render(context, request)
  File "/home/taiga/.virtualenvs/taiga/lib/python3.4/site-packages/django/template/backends/django.py", line 64, in render
    context = make_context(context, request, autoescape=self.backend.engine.autoescape)
  File "/home/taiga/.virtualenvs/taiga/lib/python3.4/site-packages/django/template/context.py", line 267, in make_context
    context.push(original_context)
  File "/home/taiga/.virtualenvs/taiga/lib/python3.4/site-packages/django/template/context.py", line 59, in push
    return ContextDict(self, *dicts, **kwargs)
  File "/home/taiga/.virtualenvs/taiga/lib/python3.4/site-packages/django/template/context.py", line 18, in __init__
    super(ContextDict, self).__init__(*args, **kwargs)
ValueError: dictionary update sequence element #0 has length 6; 2 is required
2017-05-15 14:55:41,153:basehttp "GET /user/ HTTP/1.1" 500 95356
2017-05-15 14:56:27,925:exception Internal Server Error: /user/
Traceback (most recent call last):
  File "/home/taiga/.virtualenvs/taiga/lib/python3.4/site-packages/django/core/handlers/exception.py", line 42, in inner
    response = get_response(request)
  File "/home/taiga/.virtualenvs/taiga/lib/python3.4/site-packages/django/core/handlers/base.py", line 187, in _get_response
    response = self.process_exception_by_middleware(e, request)
  File "/home/taiga/.virtualenvs/taiga/lib/python3.4/site-packages/django/core/handlers/base.py", line 185, in _get_response
    response = wrapped_callback(request, *callback_args, **callback_kwargs)
  File "/taiga-back/taiga/users/views.py", line 8, in users_list
    return render(request, 'users_list.tmpl', type(users))
  File "/home/taiga/.virtualenvs/taiga/lib/python3.4/site-packages/django/shortcuts.py", line 30, in render
    content = loader.render_to_string(template_name, context, request, using=using)
  File "/home/taiga/.virtualenvs/taiga/lib/python3.4/site-packages/django/template/loader.py", line 68, in render_to_string
    return template.render(context, request)
  File "/home/taiga/.virtualenvs/taiga/lib/python3.4/site-packages/django/template/backends/django.py", line 64, in render
    context = make_context(context, request, autoescape=self.backend.engine.autoescape)
  File "/home/taiga/.virtualenvs/taiga/lib/python3.4/site-packages/django/template/context.py", line 267, in make_context
    context.push(original_context)
  File "/home/taiga/.virtualenvs/taiga/lib/python3.4/site-packages/django/template/context.py", line 59, in push
    return ContextDict(self, *dicts, **kwargs)
  File "/home/taiga/.virtualenvs/taiga/lib/python3.4/site-packages/django/template/context.py", line 18, in __init__
    super(ContextDict, self).__init__(*args, **kwargs)
TypeError: 'type' object is not iterable
2017-05-15 14:56:28,025:basehttp "GET /user/ HTTP/1.1" 500 90764
2017-05-15 14:57:13,716:exception Internal Server Error: /user/
Traceback (most recent call last):
  File "/home/taiga/.virtualenvs/taiga/lib/python3.4/site-packages/django/core/handlers/exception.py", line 42, in inner
    response = get_response(request)
  File "/home/taiga/.virtualenvs/taiga/lib/python3.4/site-packages/django/core/handlers/base.py", line 187, in _get_response
    response = self.process_exception_by_middleware(e, request)
  File "/home/taiga/.virtualenvs/taiga/lib/python3.4/site-packages/django/core/handlers/base.py", line 185, in _get_response
    response = wrapped_callback(request, *callback_args, **callback_kwargs)
  File "/taiga-back/taiga/users/views.py", line 9, in users_list
    return render(request, 'users_list.tmpl', users)
  File "/home/taiga/.virtualenvs/taiga/lib/python3.4/site-packages/django/shortcuts.py", line 30, in render
    content = loader.render_to_string(template_name, context, request, using=using)
  File "/home/taiga/.virtualenvs/taiga/lib/python3.4/site-packages/django/template/loader.py", line 68, in render_to_string
    return template.render(context, request)
  File "/home/taiga/.virtualenvs/taiga/lib/python3.4/site-packages/django/template/backends/django.py", line 64, in render
    context = make_context(context, request, autoescape=self.backend.engine.autoescape)
  File "/home/taiga/.virtualenvs/taiga/lib/python3.4/site-packages/django/template/context.py", line 267, in make_context
    context.push(original_context)
  File "/home/taiga/.virtualenvs/taiga/lib/python3.4/site-packages/django/template/context.py", line 59, in push
    return ContextDict(self, *dicts, **kwargs)
  File "/home/taiga/.virtualenvs/taiga/lib/python3.4/site-packages/django/template/context.py", line 18, in __init__
    super(ContextDict, self).__init__(*args, **kwargs)
TypeError: 'type' object is not iterable
2017-05-15 14:57:13,804:basehttp "GET /user/ HTTP/1.1" 500 90180
2017-05-15 14:57:24,159:exception Internal Server Error: /user/
Traceback (most recent call last):
  File "/home/taiga/.virtualenvs/taiga/lib/python3.4/site-packages/django/core/handlers/exception.py", line 42, in inner
    response = get_response(request)
  File "/home/taiga/.virtualenvs/taiga/lib/python3.4/site-packages/django/core/handlers/base.py", line 187, in _get_response
    response = self.process_exception_by_middleware(e, request)
  File "/home/taiga/.virtualenvs/taiga/lib/python3.4/site-packages/django/core/handlers/base.py", line 185, in _get_response
    response = wrapped_callback(request, *callback_args, **callback_kwargs)
  File "/taiga-back/taiga/users/views.py", line 8, in users_list
    users = type(users)
NameError: name 'user' is not defined
2017-05-15 14:57:24,269:basehttp "GET /user/ HTTP/1.1" 500 65297
2017-05-15 14:57:29,390:exception Internal Server Error: /user/
Traceback (most recent call last):
  File "/home/taiga/.virtualenvs/taiga/lib/python3.4/site-packages/django/core/handlers/exception.py", line 42, in inner
    response = get_response(request)
  File "/home/taiga/.virtualenvs/taiga/lib/python3.4/site-packages/django/core/handlers/base.py", line 187, in _get_response
    response = self.process_exception_by_middleware(e, request)
  File "/home/taiga/.virtualenvs/taiga/lib/python3.4/site-packages/django/core/handlers/base.py", line 185, in _get_response
    response = wrapped_callback(request, *callback_args, **callback_kwargs)
  File "/taiga-back/taiga/users/views.py", line 9, in users_list
    return render(request, 'users_list.tmpl', users)
  File "/home/taiga/.virtualenvs/taiga/lib/python3.4/site-packages/django/shortcuts.py", line 30, in render
    content = loader.render_to_string(template_name, context, request, using=using)
  File "/home/taiga/.virtualenvs/taiga/lib/python3.4/site-packages/django/template/loader.py", line 68, in render_to_string
    return template.render(context, request)
  File "/home/taiga/.virtualenvs/taiga/lib/python3.4/site-packages/django/template/backends/django.py", line 64, in render
    context = make_context(context, request, autoescape=self.backend.engine.autoescape)
  File "/home/taiga/.virtualenvs/taiga/lib/python3.4/site-packages/django/template/context.py", line 267, in make_context
    context.push(original_context)
  File "/home/taiga/.virtualenvs/taiga/lib/python3.4/site-packages/django/template/context.py", line 59, in push
    return ContextDict(self, *dicts, **kwargs)
  File "/home/taiga/.virtualenvs/taiga/lib/python3.4/site-packages/django/template/context.py", line 18, in __init__
    super(ContextDict, self).__init__(*args, **kwargs)
TypeError: 'type' object is not iterable
2017-05-15 14:57:29,491:basehttp "GET /user/ HTTP/1.1" 500 90180
2017-05-15 14:58:05,147:exception Internal Server Error: /user/
Traceback (most recent call last):
  File "/home/taiga/.virtualenvs/taiga/lib/python3.4/site-packages/django/core/handlers/exception.py", line 42, in inner
    response = get_response(request)
  File "/home/taiga/.virtualenvs/taiga/lib/python3.4/site-packages/django/core/handlers/base.py", line 187, in _get_response
    response = self.process_exception_by_middleware(e, request)
  File "/home/taiga/.virtualenvs/taiga/lib/python3.4/site-packages/django/core/handlers/base.py", line 185, in _get_response
    response = wrapped_callback(request, *callback_args, **callback_kwargs)
  File "/taiga-back/taiga/users/views.py", line 9, in users_list
    return render(request, 'users_list.tmpl', users)
  File "/home/taiga/.virtualenvs/taiga/lib/python3.4/site-packages/django/shortcuts.py", line 30, in render
    content = loader.render_to_string(template_name, context, request, using=using)
  File "/home/taiga/.virtualenvs/taiga/lib/python3.4/site-packages/django/template/loader.py", line 68, in render_to_string
    return template.render(context, request)
  File "/home/taiga/.virtualenvs/taiga/lib/python3.4/site-packages/django/template/backends/django.py", line 64, in render
    context = make_context(context, request, autoescape=self.backend.engine.autoescape)
  File "/home/taiga/.virtualenvs/taiga/lib/python3.4/site-packages/django/template/context.py", line 267, in make_context
    context.push(original_context)
  File "/home/taiga/.virtualenvs/taiga/lib/python3.4/site-packages/django/template/context.py", line 59, in push
    return ContextDict(self, *dicts, **kwargs)
  File "/home/taiga/.virtualenvs/taiga/lib/python3.4/site-packages/django/template/context.py", line 18, in __init__
    super(ContextDict, self).__init__(*args, **kwargs)
ValueError: dictionary update sequence element #0 has length 6; 2 is required
2017-05-15 14:58:05,237:basehttp "GET /user/ HTTP/1.1" 500 95531
2017-05-15 14:58:16,753:exception Internal Server Error: /user/
Traceback (most recent call last):
  File "/home/taiga/.virtualenvs/taiga/lib/python3.4/site-packages/django/core/handlers/exception.py", line 42, in inner
    response = get_response(request)
  File "/home/taiga/.virtualenvs/taiga/lib/python3.4/site-packages/django/core/handlers/base.py", line 187, in _get_response
    response = self.process_exception_by_middleware(e, request)
  File "/home/taiga/.virtualenvs/taiga/lib/python3.4/site-packages/django/core/handlers/base.py", line 185, in _get_response
    response = wrapped_callback(request, *callback_args, **callback_kwargs)
  File "/taiga-back/taiga/users/views.py", line 8, in users_list
    users = dict(users)
ValueError: dictionary update sequence element #0 has length 6; 2 is required
2017-05-15 14:58:16,850:basehttp "GET /user/ HTTP/1.1" 500 65425
2017-05-15 14:59:19,885:exception Internal Server Error: /user/
Traceback (most recent call last):
  File "/home/taiga/.virtualenvs/taiga/lib/python3.4/site-packages/django/core/handlers/exception.py", line 42, in inner
    response = get_response(request)
  File "/home/taiga/.virtualenvs/taiga/lib/python3.4/site-packages/django/core/handlers/base.py", line 187, in _get_response
    response = self.process_exception_by_middleware(e, request)
  File "/home/taiga/.virtualenvs/taiga/lib/python3.4/site-packages/django/core/handlers/base.py", line 185, in _get_response
    response = wrapped_callback(request, *callback_args, **callback_kwargs)
  File "/taiga-back/taiga/users/views.py", line 9, in users_list
    return render(request, 'users_list.tmpl', users)
  File "/home/taiga/.virtualenvs/taiga/lib/python3.4/site-packages/django/shortcuts.py", line 30, in render
    content = loader.render_to_string(template_name, context, request, using=using)
  File "/home/taiga/.virtualenvs/taiga/lib/python3.4/site-packages/django/template/loader.py", line 68, in render_to_string
    return template.render(context, request)
  File "/home/taiga/.virtualenvs/taiga/lib/python3.4/site-packages/django/template/backends/django.py", line 64, in render
    context = make_context(context, request, autoescape=self.backend.engine.autoescape)
  File "/home/taiga/.virtualenvs/taiga/lib/python3.4/site-packages/django/template/context.py", line 267, in make_context
    context.push(original_context)
  File "/home/taiga/.virtualenvs/taiga/lib/python3.4/site-packages/django/template/context.py", line 59, in push
    return ContextDict(self, *dicts, **kwargs)
  File "/home/taiga/.virtualenvs/taiga/lib/python3.4/site-packages/django/template/context.py", line 18, in __init__
    super(ContextDict, self).__init__(*args, **kwargs)
ValueError: dictionary update sequence element #0 has length 6; 2 is required
2017-05-15 14:59:19,968:basehttp "GET /user/ HTTP/1.1" 500 95348
2017-05-15 14:59:35,260:exception Internal Server Error: /user/
Traceback (most recent call last):
  File "/home/taiga/.virtualenvs/taiga/lib/python3.4/site-packages/django/core/handlers/exception.py", line 42, in inner
    response = get_response(request)
  File "/home/taiga/.virtualenvs/taiga/lib/python3.4/site-packages/django/core/handlers/base.py", line 187, in _get_response
    response = self.process_exception_by_middleware(e, request)
  File "/home/taiga/.virtualenvs/taiga/lib/python3.4/site-packages/django/core/handlers/base.py", line 185, in _get_response
    response = wrapped_callback(request, *callback_args, **callback_kwargs)
  File "/taiga-back/taiga/users/views.py", line 9, in users_list
    return render(request, 'users_list.tmpl', users)
  File "/home/taiga/.virtualenvs/taiga/lib/python3.4/site-packages/django/shortcuts.py", line 30, in render
    content = loader.render_to_string(template_name, context, request, using=using)
  File "/home/taiga/.virtualenvs/taiga/lib/python3.4/site-packages/django/template/loader.py", line 68, in render_to_string
    return template.render(context, request)
  File "/home/taiga/.virtualenvs/taiga/lib/python3.4/site-packages/django/template/backends/django.py", line 64, in render
    context = make_context(context, request, autoescape=self.backend.engine.autoescape)
  File "/home/taiga/.virtualenvs/taiga/lib/python3.4/site-packages/django/template/context.py", line 267, in make_context
    context.push(original_context)
  File "/home/taiga/.virtualenvs/taiga/lib/python3.4/site-packages/django/template/context.py", line 59, in push
    return ContextDict(self, *dicts, **kwargs)
  File "/home/taiga/.virtualenvs/taiga/lib/python3.4/site-packages/django/template/context.py", line 18, in __init__
    super(ContextDict, self).__init__(*args, **kwargs)
ValueError: dictionary update sequence element #0 has length 6; 2 is required
2017-05-15 14:59:35,348:basehttp "GET /user/ HTTP/1.1" 500 95348
2017-05-15 14:59:35,914:exception Internal Server Error: /user/
Traceback (most recent call last):
  File "/home/taiga/.virtualenvs/taiga/lib/python3.4/site-packages/django/core/handlers/exception.py", line 42, in inner
    response = get_response(request)
  File "/home/taiga/.virtualenvs/taiga/lib/python3.4/site-packages/django/core/handlers/base.py", line 187, in _get_response
    response = self.process_exception_by_middleware(e, request)
  File "/home/taiga/.virtualenvs/taiga/lib/python3.4/site-packages/django/core/handlers/base.py", line 185, in _get_response
    response = wrapped_callback(request, *callback_args, **callback_kwargs)
  File "/taiga-back/taiga/users/views.py", line 9, in users_list
    return render(request, 'users_list.tmpl', users)
  File "/home/taiga/.virtualenvs/taiga/lib/python3.4/site-packages/django/shortcuts.py", line 30, in render
    content = loader.render_to_string(template_name, context, request, using=using)
  File "/home/taiga/.virtualenvs/taiga/lib/python3.4/site-packages/django/template/loader.py", line 68, in render_to_string
    return template.render(context, request)
  File "/home/taiga/.virtualenvs/taiga/lib/python3.4/site-packages/django/template/backends/django.py", line 64, in render
    context = make_context(context, request, autoescape=self.backend.engine.autoescape)
  File "/home/taiga/.virtualenvs/taiga/lib/python3.4/site-packages/django/template/context.py", line 267, in make_context
    context.push(original_context)
  File "/home/taiga/.virtualenvs/taiga/lib/python3.4/site-packages/django/template/context.py", line 59, in push
    return ContextDict(self, *dicts, **kwargs)
  File "/home/taiga/.virtualenvs/taiga/lib/python3.4/site-packages/django/template/context.py", line 18, in __init__
    super(ContextDict, self).__init__(*args, **kwargs)
ValueError: dictionary update sequence element #0 has length 6; 2 is required
2017-05-15 14:59:36,063:basehttp "GET /user/ HTTP/1.1" 500 95348
2017-05-15 15:00:24,417:exception Internal Server Error: /user/
Traceback (most recent call last):
  File "/home/taiga/.virtualenvs/taiga/lib/python3.4/site-packages/django/core/handlers/exception.py", line 42, in inner
    response = get_response(request)
  File "/home/taiga/.virtualenvs/taiga/lib/python3.4/site-packages/django/core/handlers/base.py", line 187, in _get_response
    response = self.process_exception_by_middleware(e, request)
  File "/home/taiga/.virtualenvs/taiga/lib/python3.4/site-packages/django/core/handlers/base.py", line 185, in _get_response
    response = wrapped_callback(request, *callback_args, **callback_kwargs)
  File "/taiga-back/taiga/users/views.py", line 9, in users_list
    return render(request, 'users_list.tmpl', users)
  File "/home/taiga/.virtualenvs/taiga/lib/python3.4/site-packages/django/shortcuts.py", line 30, in render
    content = loader.render_to_string(template_name, context, request, using=using)
  File "/home/taiga/.virtualenvs/taiga/lib/python3.4/site-packages/django/template/loader.py", line 68, in render_to_string
    return template.render(context, request)
  File "/home/taiga/.virtualenvs/taiga/lib/python3.4/site-packages/django/template/backends/django.py", line 64, in render
    context = make_context(context, request, autoescape=self.backend.engine.autoescape)
  File "/home/taiga/.virtualenvs/taiga/lib/python3.4/site-packages/django/template/context.py", line 267, in make_context
    context.push(original_context)
  File "/home/taiga/.virtualenvs/taiga/lib/python3.4/site-packages/django/template/context.py", line 59, in push
    return ContextDict(self, *dicts, **kwargs)
  File "/home/taiga/.virtualenvs/taiga/lib/python3.4/site-packages/django/template/context.py", line 18, in __init__
    super(ContextDict, self).__init__(*args, **kwargs)
ValueError: dictionary update sequence element #0 has length 6; 2 is required
2017-05-15 15:00:24,507:basehttp "GET /user/ HTTP/1.1" 500 95348
2017-05-15 15:00:25,989:exception Internal Server Error: /user/
Traceback (most recent call last):
  File "/home/taiga/.virtualenvs/taiga/lib/python3.4/site-packages/django/core/handlers/exception.py", line 42, in inner
    response = get_response(request)
  File "/home/taiga/.virtualenvs/taiga/lib/python3.4/site-packages/django/core/handlers/base.py", line 187, in _get_response
    response = self.process_exception_by_middleware(e, request)
  File "/home/taiga/.virtualenvs/taiga/lib/python3.4/site-packages/django/core/handlers/base.py", line 185, in _get_response
    response = wrapped_callback(request, *callback_args, **callback_kwargs)
  File "/taiga-back/taiga/users/views.py", line 9, in users_list
    return render(request, 'users_list.tmpl', users)
  File "/home/taiga/.virtualenvs/taiga/lib/python3.4/site-packages/django/shortcuts.py", line 30, in render
    content = loader.render_to_string(template_name, context, request, using=using)
  File "/home/taiga/.virtualenvs/taiga/lib/python3.4/site-packages/django/template/loader.py", line 68, in render_to_string
    return template.render(context, request)
  File "/home/taiga/.virtualenvs/taiga/lib/python3.4/site-packages/django/template/backends/django.py", line 64, in render
    context = make_context(context, request, autoescape=self.backend.engine.autoescape)
  File "/home/taiga/.virtualenvs/taiga/lib/python3.4/site-packages/django/template/context.py", line 267, in make_context
    context.push(original_context)
  File "/home/taiga/.virtualenvs/taiga/lib/python3.4/site-packages/django/template/context.py", line 59, in push
    return ContextDict(self, *dicts, **kwargs)
  File "/home/taiga/.virtualenvs/taiga/lib/python3.4/site-packages/django/template/context.py", line 18, in __init__
    super(ContextDict, self).__init__(*args, **kwargs)
ValueError: dictionary update sequence element #0 has length 6; 2 is required
2017-05-15 15:00:26,097:basehttp "GET /user/ HTTP/1.1" 500 95348
2017-05-15 15:00:44,979:exception Internal Server Error: /user/
Traceback (most recent call last):
  File "/home/taiga/.virtualenvs/taiga/lib/python3.4/site-packages/django/core/handlers/exception.py", line 42, in inner
    response = get_response(request)
  File "/home/taiga/.virtualenvs/taiga/lib/python3.4/site-packages/django/core/handlers/base.py", line 187, in _get_response
    response = self.process_exception_by_middleware(e, request)
  File "/home/taiga/.virtualenvs/taiga/lib/python3.4/site-packages/django/core/handlers/base.py", line 185, in _get_response
    response = wrapped_callback(request, *callback_args, **callback_kwargs)
  File "/taiga-back/taiga/users/views.py", line 9, in users_list
    return render(request, 'users_list.tmpl', user)
  File "/home/taiga/.virtualenvs/taiga/lib/python3.4/site-packages/django/shortcuts.py", line 30, in render
    content = loader.render_to_string(template_name, context, request, using=using)
  File "/home/taiga/.virtualenvs/taiga/lib/python3.4/site-packages/django/template/loader.py", line 68, in render_to_string
    return template.render(context, request)
  File "/home/taiga/.virtualenvs/taiga/lib/python3.4/site-packages/django/template/backends/django.py", line 64, in render
    context = make_context(context, request, autoescape=self.backend.engine.autoescape)
  File "/home/taiga/.virtualenvs/taiga/lib/python3.4/site-packages/django/template/context.py", line 267, in make_context
    context.push(original_context)
  File "/home/taiga/.virtualenvs/taiga/lib/python3.4/site-packages/django/template/context.py", line 59, in push
    return ContextDict(self, *dicts, **kwargs)
  File "/home/taiga/.virtualenvs/taiga/lib/python3.4/site-packages/django/template/context.py", line 18, in __init__
    super(ContextDict, self).__init__(*args, **kwargs)
ValueError: dictionary update sequence element #0 has length 6; 2 is required
2017-05-15 15:00:45,072:basehttp "GET /user/ HTTP/1.1" 500 96112
2017-05-15 15:00:46,274:exception Internal Server Error: /user/
Traceback (most recent call last):
  File "/home/taiga/.virtualenvs/taiga/lib/python3.4/site-packages/django/core/handlers/exception.py", line 42, in inner
    response = get_response(request)
  File "/home/taiga/.virtualenvs/taiga/lib/python3.4/site-packages/django/core/handlers/base.py", line 187, in _get_response
    response = self.process_exception_by_middleware(e, request)
  File "/home/taiga/.virtualenvs/taiga/lib/python3.4/site-packages/django/core/handlers/base.py", line 185, in _get_response
    response = wrapped_callback(request, *callback_args, **callback_kwargs)
  File "/taiga-back/taiga/users/views.py", line 9, in users_list
    return render(request, 'users_list.tmpl', user)
  File "/home/taiga/.virtualenvs/taiga/lib/python3.4/site-packages/django/shortcuts.py", line 30, in render
    content = loader.render_to_string(template_name, context, request, using=using)
  File "/home/taiga/.virtualenvs/taiga/lib/python3.4/site-packages/django/template/loader.py", line 68, in render_to_string
    return template.render(context, request)
  File "/home/taiga/.virtualenvs/taiga/lib/python3.4/site-packages/django/template/backends/django.py", line 64, in render
    context = make_context(context, request, autoescape=self.backend.engine.autoescape)
  File "/home/taiga/.virtualenvs/taiga/lib/python3.4/site-packages/django/template/context.py", line 267, in make_context
    context.push(original_context)
  File "/home/taiga/.virtualenvs/taiga/lib/python3.4/site-packages/django/template/context.py", line 59, in push
    return ContextDict(self, *dicts, **kwargs)
  File "/home/taiga/.virtualenvs/taiga/lib/python3.4/site-packages/django/template/context.py", line 18, in __init__
    super(ContextDict, self).__init__(*args, **kwargs)
ValueError: dictionary update sequence element #0 has length 6; 2 is required
2017-05-15 15:00:46,384:basehttp "GET /user/ HTTP/1.1" 500 96112
2017-05-15 15:03:04,417:exception Internal Server Error: /user/
Traceback (most recent call last):
  File "/home/taiga/.virtualenvs/taiga/lib/python3.4/site-packages/django/core/handlers/exception.py", line 42, in inner
    response = get_response(request)
  File "/home/taiga/.virtualenvs/taiga/lib/python3.4/site-packages/django/core/handlers/base.py", line 187, in _get_response
    response = self.process_exception_by_middleware(e, request)
  File "/home/taiga/.virtualenvs/taiga/lib/python3.4/site-packages/django/core/handlers/base.py", line 185, in _get_response
    response = wrapped_callback(request, *callback_args, **callback_kwargs)
  File "/taiga-back/taiga/users/views.py", line 8, in users_list
    user['data'] = users
NameError: name 'user' is not defined
2017-05-15 15:03:04,508:basehttp "GET /user/ HTTP/1.1" 500 65314
2017-05-15 15:03:21,195:basehttp "GET /user/ HTTP/1.1" 200 7
2017-05-15 15:03:45,732:basehttp "GET /user/ HTTP/1.1" 200 2
2017-05-15 15:03:46,735:basehttp "GET /user/ HTTP/1.1" 200 2
2017-05-15 15:04:00,792:basehttp "GET /user/ HTTP/1.1" 200 2
2017-05-15 15:04:01,425:basehttp "GET /user/ HTTP/1.1" 200 2
2017-05-15 15:04:07,023:basehttp "GET /user/ HTTP/1.1" 200 7
2017-05-15 15:04:44,209:exception Internal Server Error: /user/
Traceback (most recent call last):
  File "/home/taiga/.virtualenvs/taiga/lib/python3.4/site-packages/django/core/handlers/exception.py", line 42, in inner
    response = get_response(request)
  File "/home/taiga/.virtualenvs/taiga/lib/python3.4/site-packages/django/core/handlers/base.py", line 187, in _get_response
    response = self.process_exception_by_middleware(e, request)
  File "/home/taiga/.virtualenvs/taiga/lib/python3.4/site-packages/django/core/handlers/base.py", line 185, in _get_response
    response = wrapped_callback(request, *callback_args, **callback_kwargs)
  File "/taiga-back/taiga/users/views.py", line 7, in users_list
    users = User.objects.get(id>=1)
TypeError: unorderable types: builtin_function_or_method() >= int()
2017-05-15 15:04:44,298:basehttp "GET /user/ HTTP/1.1" 500 64497
2017-05-15 15:04:51,793:exception Internal Server Error: /user/
Traceback (most recent call last):
  File "/home/taiga/.virtualenvs/taiga/lib/python3.4/site-packages/django/core/handlers/exception.py", line 42, in inner
    response = get_response(request)
  File "/home/taiga/.virtualenvs/taiga/lib/python3.4/site-packages/django/core/handlers/base.py", line 187, in _get_response
    response = self.process_exception_by_middleware(e, request)
  File "/home/taiga/.virtualenvs/taiga/lib/python3.4/site-packages/django/core/handlers/base.py", line 185, in _get_response
    response = wrapped_callback(request, *callback_args, **callback_kwargs)
  File "/taiga-back/taiga/users/views.py", line 7, in users_list
    users = User.objects.get(id>1)
TypeError: unorderable types: builtin_function_or_method() > int()
2017-05-15 15:04:51,878:basehttp "GET /user/ HTTP/1.1" 500 64491
2017-05-15 15:05:10,298:basehttp "GET /user/ HTTP/1.1" 200 7
2017-05-15 15:05:57,355:basehttp "GET /user/3 HTTP/1.1" 301 0
2017-05-15 15:05:57,376:basehttp "GET /user/3/ HTTP/1.1" 200 46
2017-05-15 15:06:00,764:basehttp "GET /user/ HTTP/1.1" 200 7
2017-05-15 15:06:01,112:basehttp "GET /user/2 HTTP/1.1" 301 0
2017-05-15 15:06:01,137:basehttp "GET /user/2/ HTTP/1.1" 200 46
2017-05-15 15:07:03,876:basehttp "GET /user/2/ HTTP/1.1" 200 46
2017-05-15 15:07:08,436:exception Internal Server Error: /user/
Traceback (most recent call last):
  File "/home/taiga/.virtualenvs/taiga/lib/python3.4/site-packages/django/core/handlers/exception.py", line 42, in inner
    response = get_response(request)
  File "/home/taiga/.virtualenvs/taiga/lib/python3.4/site-packages/django/core/handlers/base.py", line 187, in _get_response
    response = self.process_exception_by_middleware(e, request)
  File "/home/taiga/.virtualenvs/taiga/lib/python3.4/site-packages/django/core/handlers/base.py", line 185, in _get_response
    response = wrapped_callback(request, *callback_args, **callback_kwargs)
  File "/taiga-back/taiga/users/views.py", line 9, in users_list
    args['data'] = users.name
AttributeError: 'User' object has no attribute 'name'
2017-05-15 15:07:08,511:basehttp "GET /user/ HTTP/1.1" 500 64838
2017-05-15 15:07:09,579:exception Internal Server Error: /user/
Traceback (most recent call last):
  File "/home/taiga/.virtualenvs/taiga/lib/python3.4/site-packages/django/core/handlers/exception.py", line 42, in inner
    response = get_response(request)
  File "/home/taiga/.virtualenvs/taiga/lib/python3.4/site-packages/django/core/handlers/base.py", line 187, in _get_response
    response = self.process_exception_by_middleware(e, request)
  File "/home/taiga/.virtualenvs/taiga/lib/python3.4/site-packages/django/core/handlers/base.py", line 185, in _get_response
    response = wrapped_callback(request, *callback_args, **callback_kwargs)
  File "/taiga-back/taiga/users/views.py", line 9, in users_list
    args['data'] = users.name
AttributeError: 'User' object has no attribute 'name'
2017-05-15 15:07:09,656:basehttp "GET /user/ HTTP/1.1" 500 64973
2017-05-15 15:07:19,341:basehttp "GET /user/ HTTP/1.1" 200 2
2017-05-15 15:07:20,054:basehttp "GET /user/ HTTP/1.1" 200 2
2017-05-15 15:07:31,747:basehttp "GET /user/ HTTP/1.1" 200 7
2017-05-15 15:08:18,451:basehttp "GET /user/ HTTP/1.1" 200 46
2017-05-15 15:08:44,327:exception Internal Server Error: /user/
Traceback (most recent call last):
  File "/home/taiga/.virtualenvs/taiga/lib/python3.4/site-packages/django/core/handlers/exception.py", line 42, in inner
    response = get_response(request)
  File "/home/taiga/.virtualenvs/taiga/lib/python3.4/site-packages/django/core/handlers/base.py", line 187, in _get_response
    response = self.process_exception_by_middleware(e, request)
  File "/home/taiga/.virtualenvs/taiga/lib/python3.4/site-packages/django/core/handlers/base.py", line 185, in _get_response
    response = wrapped_callback(request, *callback_args, **callback_kwargs)
  File "/taiga-back/taiga/users/views.py", line 9, in users_list
    user = User.objects.get(id>user_id)
TypeError: unorderable types: builtin_function_or_method() > int()
2017-05-15 15:08:44,400:basehttp "GET /user/ HTTP/1.1" 500 64945
2017-05-15 15:10:57,735:exception Internal Server Error: /user/
Traceback (most recent call last):
  File "/home/taiga/.virtualenvs/taiga/lib/python3.4/site-packages/django/core/handlers/exception.py", line 42, in inner
    response = get_response(request)
  File "/home/taiga/.virtualenvs/taiga/lib/python3.4/site-packages/django/core/handlers/base.py", line 187, in _get_response
    response = self.process_exception_by_middleware(e, request)
  File "/home/taiga/.virtualenvs/taiga/lib/python3.4/site-packages/django/core/handlers/base.py", line 185, in _get_response
    response = wrapped_callback(request, *callback_args, **callback_kwargs)
  File "/taiga-back/taiga/users/views.py", line 9, in users_list
    user = User.objects.get(id__gte=user_id)
  File "/home/taiga/.virtualenvs/taiga/lib/python3.4/site-packages/django/db/models/manager.py", line 85, in manager_method
    return getattr(self.get_queryset(), name)(*args, **kwargs)
  File "/home/taiga/.virtualenvs/taiga/lib/python3.4/site-packages/django/db/models/query.py", line 389, in get
    (self.model._meta.object_name, num)
taiga.users.models.MultipleObjectsReturned: get() returned more than one User -- it returned 3!
2017-05-15 15:10:57,823:basehttp "GET /user/ HTTP/1.1" 500 73796
2017-05-15 15:11:37,546:exception Internal Server Error: /user/
Traceback (most recent call last):
  File "/home/taiga/.virtualenvs/taiga/lib/python3.4/site-packages/django/core/handlers/exception.py", line 42, in inner
    response = get_response(request)
  File "/home/taiga/.virtualenvs/taiga/lib/python3.4/site-packages/django/core/handlers/base.py", line 187, in _get_response
    response = self.process_exception_by_middleware(e, request)
  File "/home/taiga/.virtualenvs/taiga/lib/python3.4/site-packages/django/core/handlers/base.py", line 185, in _get_response
    response = wrapped_callback(request, *callback_args, **callback_kwargs)
  File "/taiga-back/taiga/users/views.py", line 9, in users_list
    user = User.objects.get(id__gte=user_id)
  File "/home/taiga/.virtualenvs/taiga/lib/python3.4/site-packages/django/db/models/manager.py", line 85, in manager_method
    return getattr(self.get_queryset(), name)(*args, **kwargs)
  File "/home/taiga/.virtualenvs/taiga/lib/python3.4/site-packages/django/db/models/query.py", line 389, in get
    (self.model._meta.object_name, num)
taiga.users.models.MultipleObjectsReturned: get() returned more than one User -- it returned 3!
2017-05-15 15:11:37,637:basehttp "GET /user/ HTTP/1.1" 500 73794
2017-05-15 15:14:13,277:basehttp "GET /user/ HTTP/1.1" 200 2
2017-05-15 15:14:25,418:exception Internal Server Error: /user/
Traceback (most recent call last):
  File "/home/taiga/.virtualenvs/taiga/lib/python3.4/site-packages/django/core/handlers/exception.py", line 42, in inner
    response = get_response(request)
  File "/home/taiga/.virtualenvs/taiga/lib/python3.4/site-packages/django/core/handlers/base.py", line 187, in _get_response
    response = self.process_exception_by_middleware(e, request)
  File "/home/taiga/.virtualenvs/taiga/lib/python3.4/site-packages/django/core/handlers/base.py", line 185, in _get_response
    response = wrapped_callback(request, *callback_args, **callback_kwargs)
  File "/taiga-back/taiga/users/views.py", line 10, in users_list
    return render(request, 'users_list.tmpl', users)
  File "/home/taiga/.virtualenvs/taiga/lib/python3.4/site-packages/django/shortcuts.py", line 30, in render
    content = loader.render_to_string(template_name, context, request, using=using)
  File "/home/taiga/.virtualenvs/taiga/lib/python3.4/site-packages/django/template/loader.py", line 68, in render_to_string
    return template.render(context, request)
  File "/home/taiga/.virtualenvs/taiga/lib/python3.4/site-packages/django/template/backends/django.py", line 64, in render
    context = make_context(context, request, autoescape=self.backend.engine.autoescape)
  File "/home/taiga/.virtualenvs/taiga/lib/python3.4/site-packages/django/template/context.py", line 267, in make_context
    context.push(original_context)
  File "/home/taiga/.virtualenvs/taiga/lib/python3.4/site-packages/django/template/context.py", line 59, in push
    return ContextDict(self, *dicts, **kwargs)
  File "/home/taiga/.virtualenvs/taiga/lib/python3.4/site-packages/django/template/context.py", line 18, in __init__
    super(ContextDict, self).__init__(*args, **kwargs)
TypeError: cannot convert dictionary update sequence element #0 to a sequence
2017-05-15 15:14:25,504:basehttp "GET /user/ HTTP/1.1" 500 90804
2017-05-15 15:19:08,637:basehttp "GET /user/ HTTP/1.1" 200 1
2017-05-15 15:21:03,232:basehttp "GET /user/ HTTP/1.1" 200 55
2017-05-15 15:21:39,964:basehttp "GET /user/ HTTP/1.1" 200 79
2017-05-15 15:21:53,884:basehttp "GET /user/ HTTP/1.1" 200 79
2017-05-15 15:22:53,171:basehttp "GET /user/ HTTP/1.1" 200 79
